Workbook

Sheet 使用说明
A1: 卖家精灵选产品 → 客户期望驱动的 ASIN 动态评分表
A3: 一、核心原则
A4: 1. 必须先完成「00_客户期望配置」并确认，评分才生效。
A5: 2. 数据源严格限制为卖家精灵「选产品」真实返回字段，禁止虚构任何指标。
A6: 3. 所有权重、阈值、否决线均由客户期望动态驱动，修改后自动重算。
A8: 二、使用步骤
A9: 步骤1：到「00_客户期望配置」填写所有黄色单元格（风险偏好、价格带、毛利率、评分数上限、增长率下限、上架偏好、是否接受自营、四大权重），最后确认「是」。
A10: 步骤2：检查 B25 显示【已完成】。
A11: 步骤3：把卖家精灵选产品导出的 Excel 按「02_ASIN原始数据」表头顺序粘贴（从第3行开始）。注意 unitsGr、profit 保持数字，availableDate 尽量为日期。
A12: 步骤4：查看「04_最终评分」——红色「否决」行为一票否决；S/A/B/C 为推荐等级。
A13: 步骤5：「05_推荐清单」自动过滤出通过且总分≥6 的产品（需 Excel 365/2021+ 支持 FILTER）。
A14: 步骤6：如需调整标准，只需修改「00」的期望值，全表自动刷新。
... A26: • 黄色单元格为输入区（蓝色字体），绿色字体为跨表引用公式，黑色为计算。

Sheet 00_客户期望配置
A1: 客户期望配置（强制门禁）— 必须全部填写并确认后，评分才生效
A2: 数据源限制：仅使用卖家精灵「选产品」真实返回字段，禁止虚构任何指标
A4: 一、客户画像与硬性约束
A5: 风险偏好 | B5: 稳健 | C5: 保守=更严格否决与权重；激进=更看重增长
A6: 期望最低价格（USD） | B6: 20 | C6: 对应 price 字段，低于此价格不得高分
A7: 期望最高价格（USD） | B7: 50 | C7: 对应 price 字段，高于此价格不得高分
A8: 最低预估毛利率要求（%） | B8: 30 | C8: 对应 profit 字段，低于此值直接一票否决
A9: 最高可接受评分数 | B9: 1500 | C9: 对应 ratings 字段，超过此值直接一票否决（准入门槛）
A10: 最低可接受销量增长率（%） | B10: 10 | C10: 对应 unitsGr 字段，低于此值直接一票否决（生命周期）
A11: 上架时间偏好 | B11: 近12个月 | C11: 基于 availableDate 判断是否处于客户接受的窗口
A12: 是否接受亚马逊自营 | B12: 不接受 | C12: fulfillment=AMZ 时是否触发否决
A14: 二、权重分配（总和必须 = 100）
A15: 低竞争权重（%） | B15: 30 | C15: 评分数低 + 卖家数少 + 池内销量排名靠前
A16: 上升生命周期权重（%） | B16: 30 | C16: unitsGr 高 + 上架时间在窗口内
A17: 利润健康权重（%） | B17: 25 | C17: 价格落在期望带 + profit 达标
A18: 准入门槛低权重（%） | B18: 15 | C18: 评分数可控 + 新品窗口 + New Release
A20: 权重总和检查 | B20: =B15+B16+B17+B18 | C20: 必须等于 100，否则评分无效
A22: 三、完成确认
A23: 我已确认以上期望值，并理解评分将严格按此执行 | B23: 是
A25: 完成度检查（门禁） | B25: =IF(AND(B5<>"",B6<>"",B7<>"",B8<>"",B9<>"",B10<>"",B11<>"",B12<>"",B15<>"",B16<>"",B17<>"",B18<>"",B23="是",B20=100),"【已完成】可以进入评分","【未完成】请全部填写并确认，权重总和必须=100")
A27: 使用说明
A28: 1. 黄色单元格为客户必填输入区（蓝色字体）。2. 全部填写并确认后，B25 显示【已完成】。3. 再到 02 粘贴卖家精灵数据，04/05 自动出结果。4. 修改期望后全表自动重算。

Sheet 01_动态参数
A1: 动态参数（全部自动引用 00_客户期望配置，禁止手动修改）
A3: 权重（小数）
A4: 低竞争权重 | B4: ='00_客户期望配置'!B15/100
A5: 上升生命周期权重 | B5: ='00_客户期望配置'!B16/100
A6: 利润健康权重 | B6: ='00_客户期望配置'!B17/100
A7: 准入门槛低权重 | B7: ='00_客户期望配置'!B18/100
A9: 阈值与否决线
A10: 价格下限 | B10: ='00_客户期望配置'!B6
A11: 价格上限 | B11: ='00_客户期望配置'!B7
A12: 毛利率否决线（%） | B12: ='00_客户期望配置'!B8
A13: 评分数否决线 | B13: ='00_客户期望配置'!B9
A14: 增长率否决线（%） | B14: ='00_客户期望配置'!B10
A15: 上架时间偏好（天） | B15: =IF('00_客户期望配置'!B11="近6个月",180,IF('00_客户期望配置'!B11="近12个月",365,9999))
A16: 是否否决自营（1=是） | B16: =IF('00_客户期望配置'!B12="不接受",1,0)
A18: 说明：本表所有值均自动从「00_客户期望配置」拉取，客户修改期望后此处实时更新，驱动后续打分与否决。

Sheet 02_ASIN原始数据
A1: ASIN原始数据（请将卖家精灵「选产品」导出结果按下列字段顺序粘贴，从第2行开始）
A2: asin | B2: title | C2: brand | D2: price | E2: units | F2: unitsGr | G2: revenue | H2: bsr | I2: rating | J2: ratings | K2: ratingsCv | L2: availableDate | M2: fulfillment | N2: profit | O2: fba | P2: sellers | Q2: badge_newRelease | R2: nodeLabelPath
A3: B0SAMPLE001 | B3: Wireless Earbuds Pro Noise Cancelling | C3: TechSound | D3: 39.99 | E3: 1250 | F3: 28.5 | G3: 49987.5 | H3: 1520 | I3: 4.3 | J3: 680 | K3: 45 | L3: 45976 | M3: FBA | N3: 42.5 | O3: 5.8 | P3: 2 | Q3: Y | R3: Electronics:Headphones
A4: B0SAMPLE002 | B4: USB-C Fast Charging Cable 3-Pack | C4: CableKing | D4: 12.99 | E4: 8900 | F4: 5.2 | G4: 115611 | H4: 320 | I4: 4.6 | J4: 15200 | K4: 320 | L4: 44995 | M4: FBA | N4: 55 | O4: 3.2 | P4: 8 | Q4: N | R4: Electronics:Cables
A5: B0SAMPLE003 | B5: Portable Blender for Smoothies | C5: BlendGo | D5: 29.99 | E5: 2100 | F5: 45 | G5: 62979 | H5: 890 | I5: 4.1 | J5: 320 | K5: 28 | L5: 46073 | M5: FBA | N5: 38 | O5: 6.5 | P5: 1 | Q5: Y | R5: Home:Kitchen
A6: B0SAMPLE004 | B6: Ergonomic Office Chair Lumbar Support | C6: SitWell | D6: 189 | E6: 450 | F6: -8.5 | G6: 85050 | H6: 5600 | I6: 4.4 | J6: 2800 | K6: 15 | L6: 45444 | M6: AMZ | N6: 28 | O6: 28 | P6: 1 | Q6: N | R6: Furniture:Office Chairs
A7: B0SAMPLE005 | B7: LED Desk Lamp with Wireless Charger | C7: LightPlus | D7: 45.5 | E7: 980 | F7: 18 | G7: 44590 | H7: 2100 | I7: 4.5 | J7: 950 | K7: 60 | L7: 45874 | M7: FBA | N7: 48 | O7: 7.1 | P7: 3 | Q7: N | R7: Home:Lighting
A54: 注意：availableDate 请尽量转为日期格式；unitsGr 与 profit 请保持为数字（百分比数值，如 15 代表 15%）；badge_newRelease 填 Y/N 或 Yes/No。

Sheet 03_衍生指标
A1: 衍生指标（自动计算，基于 02 与 01）
A2: asin | B2: 上架天数 | C2: 是否在上架窗口 | D2: 价格带匹配 | E2: 毛利率达标 | F2: 评分数超限 | G2: 增长率达标 | H2: 是否自营 | I2: 池内销量排名 | J2: 低竞争原始分 | K2: 生命周期原始分 | L2: 利润健康原始分 | M2: 准入门槛原始分 | N2: 数据行号
A3: ='02_ASIN原始数据'!A3 | B3: =IF('02_ASIN原始数据'!L3="","",IF(ISNUMBER('02_ASIN原始数据'!L3),TODAY()-'02_ASIN原始数据'!L3,"")) | C3: =IF(OR(A3="",B3=""),"",IF(B3<='01_动态参数'!B15,1,0)) | D3: =IF(A3="","",IF(AND('02_ASIN原始数据'!D3>='01_动态参数'!B10,'02_ASIN原始数据'!D3<='01_动态参数'!B11),1,0)) | E3: =IF(A3="","",IF('02_ASIN原始数据'!N3>='01_动态参数'!B12,1,0)) | F3: =IF(A3="","",IF('02_ASIN原始数据'!J3>'01_动态参数'!B13,1,0)) | G3: =IF(A3="","",IF('02_ASIN原始数据'!F3>='01_动态参数'!B14,1,0)) | H3: =IF(A3="","",IF('02_ASIN原始数据'!M3="AMZ",1,0)) | I3: =IF(A3="","",IF('02_ASIN原始数据'!E3="", "",RANK('02_ASIN原始数据'!E3,'02_ASIN原始数据'!$E$3:$E$52,0))) | J3: =IF(A3="","",MIN(10,IF('02_ASIN原始数据'!J3<=300,10,IF('02_ASIN原始数据'!J3<=800,8,IF('02_ASIN原始数据'!J3<=1500,5,IF('02_ASIN原始数据'!J3<=3000,2,0))))+IF('02_ASIN原始数据'!P3<=3,2,0)+IF(I3<=10,1,0))) | K3: =IF(A3="","",MIN(10,IF('02_ASIN原始数据'!F3>=50,10,IF('02_ASIN原始数据'!F3>=30,9,IF('02_ASIN原始数据'!F3>=15,7,IF('02_ASIN原始数据'!F3>=5,5,2))))+IF(C3=1,2,0))) | L3: =IF(A3="","",IF(E3=0,0,IF(D3=1,8,3)+IF('02_ASIN原始数据'!N3>='01_动态参数'!B12+10,2,IF('02_ASIN原始数据'!N3>='01_动态参数'!B12,1,0)))) | M3: =IF(A3="","",MIN(10,IF('02_ASIN原始数据'!J3<=500,10,IF('02_ASIN原始数据'!J3<=1000,7,IF('02_ASIN原始数据'!J3<=2000,4,1)))+IF(C3=1,2,0)+IF(OR('02_ASIN原始数据'!Q3="Y",'02_ASIN原始数据'!Q3="Yes",'02_ASIN原始数据'!Q3="YES"),1,0))) | N3: 3
A4: ='02_ASIN原始数据'!A4 | B4: =IF('02_ASIN原始数据'!L4="","",IF(ISNUMBER('02_ASIN原始数据'!L4),TODAY()-'02_ASIN原始数据'!L4,"")) | C4: =IF(OR(A4="",B4=""),"",IF(B4<='01_动态参数'!B15,1,0)) | D4: =IF(A4="","",IF(AND('02_ASIN原始数据'!D4>='01_动态参数'!B10,'02_ASIN原始数据'!D4<='01_动态参数'!B11),1,0)) | E4: =IF(A4="","",IF('02_ASIN原始数据'!N4>='01_动态参数'!B12,1,0)) | F4: =IF(A4="","",IF('02_ASIN原始数据'!J4>'01_动态参数'!B13,1,0)) | G4: =IF(A4="","",IF('02_ASIN原始数据'!F4>='01_动态参数'!B14,1,0)) | H4: =IF(A4="","",IF('02_ASIN原始数据'!M4="AMZ",1,0)) | I4: =IF(A4="","",IF('02_ASIN原始数据'!E4="", "",RANK('02_ASIN原始数据'!E4,'02_ASIN原始数据'!$E$3:$E$52,0))) | J4: =IF(A4="","",MIN(10,IF('02_ASIN原始数据'!J4<=300,10,IF('02_ASIN原始数据'!J4<=800,8,IF('02_ASIN原始数据'!J4<=1500,5,IF('02_ASIN原始数据'!J4<=3000,2,0))))+IF('02_ASIN原始数据'!P4<=3,2,0)+IF(I4<=10,1,0))) | K4: =IF(A4="","",MIN(10,IF('02_ASIN原始数据'!F4>=50,10,IF('02_ASIN原始数据'!F4>=30,9,IF('02_ASIN原始数据'!F4>=15,7,IF('02_ASIN原始数据'!F4>=5,5,2))))+IF(C4=1,2,0))) | L4: =IF(A4="","",IF(E4=0,0,IF(D4=1,8,3)+IF('02_ASIN原始数据'!N4>='01_动态参数'!B12+10,2,IF('02_ASIN原始数据'!N4>='01_动态参数'!B12,1,0)))) | M4: =IF(A4="","",MIN(10,IF('02_ASIN原始数据'!J4<=500,10,IF('02_ASIN原始数据'!J4<=1000,7,IF('02_ASIN原始数据'!J4<=2000,4,1)))+IF(C4=1,2,0)+IF(OR('02_ASIN原始数据'!Q4="Y",'02_ASIN原始数据'!Q4="Yes",'02_ASIN原始数据'!Q4="YES"),1,0))) | N4: 4
A5: ='02_ASIN原始数据'!A5 | B5: =IF('02_ASIN原始数据'!L5="","",IF(ISNUMBER('02_ASIN原始数据'!L5),TODAY()-'02_ASIN原始数据'!L5,"")) | C5: =IF(OR(A5="",B5=""),"",IF(B5<='01_动态参数'!B15,1,0)) | D5: =IF(A5="","",IF(AND('02_ASIN原始数据'!D5>='01_动态参数'!B10,'02_ASIN原始数据'!D5<='01_动态参数'!B11),1,0)) | E5: =IF(A5="","",IF('02_ASIN原始数据'!N5>='01_动态参数'!B12,1,0)) | F5: =IF(A5="","",IF('02_ASIN原始数据'!J5>'01_动态参数'!B13,1,0)) | G5: =IF(A5="","",IF('02_ASIN原始数据'!F5>='01_动态参数'!B14,1,0)) | H5: =IF(A5="","",IF('02_ASIN原始数据'!M5="AMZ",1,0)) | I5: =IF(A5="","",IF('02_ASIN原始数据'!E5="", "",RANK('02_ASIN原始数据'!E5,'02_ASIN原始数据'!$E$3:$E$52,0))) | J5: =IF(A5="","",MIN(10,IF('02_ASIN原始数据'!J5<=300,10,IF('02_ASIN原始数据'!J5<=800,8,IF('02_ASIN原始数据'!J5<=1500,5,IF('02_ASIN原始数据'!J5<=3000,2,0))))+IF('02_ASIN原始数据'!P5<=3,2,0)+IF(I5<=10,1,0))) | K5: =IF(A5="","",MIN(10,IF('02_ASIN原始数据'!F5>=50,10,IF('02_ASIN原始数据'!F5>=30,9,IF('02_ASIN原始数据'!F5>=15,7,IF('02_ASIN原始数据'!F5>=5,5,2))))+IF(C5=1,2,0))) | L5: =IF(A5="","",IF(E5=0,0,IF(D5=1,8,3)+IF('02_ASIN原始数据'!N5>='01_动态参数'!B12+10,2,IF('02_ASIN原始数据'!N5>='01_动态参数'!B12,1,0)))) | M5: =IF(A5="","",MIN(10,IF('02_ASIN原始数据'!J5<=500,10,IF('02_ASIN原始数据'!J5<=1000,7,IF('02_ASIN原始数据'!J5<=2000,4,1)))+IF(C5=1,2,0)+IF(OR('02_ASIN原始数据'!Q5="Y",'02_ASIN原始数据'!Q5="Yes",'02_ASIN原始数据'!Q5="YES"),1,0))) | N5: 5
A6: ='02_ASIN原始数据'!A6 | B6: =IF('02_ASIN原始数据'!L6="","",IF(ISNUMBER('02_ASIN原始数据'!L6),TODAY()-'02_ASIN原始数据'!L6,"")) | C6: =IF(OR(A6="",B6=""),"",IF(B6<='01_动态参数'!B15,1,0)) | D6: =IF(A6="","",IF(AND('02_ASIN原始数据'!D6>='01_动态参数'!B10,'02_ASIN原始数据'!D6<='01_动态参数'!B11),1,0)) | E6: =IF(A6="","",IF('02_ASIN原始数据'!N6>='01_动态参数'!B12,1,0)) | F6: =IF(A6="","",IF('02_ASIN原始数据'!J6>'01_动态参数'!B13,1,0)) | G6: =IF(A6="","",IF('02_ASIN原始数据'!F6>='01_动态参数'!B14,1,0)) | H6: =IF(A6="","",IF('02_ASIN原始数据'!M6="AMZ",1,0)) | I6: =IF(A6="","",IF('02_ASIN原始数据'!E6="", "",RANK('02_ASIN原始数据'!E6,'02_ASIN原始数据'!$E$3:$E$52,0))) | J6: =IF(A6="","",MIN(10,IF('02_ASIN原始数据'!J6<=300,10,IF('02_ASIN原始数据'!J6<=800,8,IF('02_ASIN原始数据'!J6<=1500,5,IF('02_ASIN原始数据'!J6<=3000,2,0))))+IF('02_ASIN原始数据'!P6<=3,2,0)+IF(I6<=10,1,0))) | K6: =IF(A6="","",MIN(10,IF('02_ASIN原始数据'!F6>=50,10,IF('02_ASIN原始数据'!F6>=30,9,IF('02_ASIN原始数据'!F6>=15,7,IF('02_ASIN原始数据'!F6>=5,5,2))))+IF(C6=1,2,0))) | L6: =IF(A6="","",IF(E6=0,0,IF(D6=1,8,3)+IF('02_ASIN原始数据'!N6>='01_动态参数'!B12+10,2,IF('02_ASIN原始数据'!N6>='01_动态参数'!B12,1,0)))) | M6: =IF(A6="","",MIN(10,IF('02_ASIN原始数据'!J6<=500,10,IF('02_ASIN原始数据'!J6<=1000,7,IF('02_ASIN原始数据'!J6<=2000,4,1)))+IF(C6=1,2,0)+IF(OR('02_ASIN原始数据'!Q6="Y",'02_ASIN原始数据'!Q6="Yes",'02_ASIN原始数据'!Q6="YES"),1,0))) | N6: 6
A7: ='02_ASIN原始数据'!A7 | B7: =IF('02_ASIN原始数据'!L7="","",IF(ISNUMBER('02_ASIN原始数据'!L7),TODAY()-'02_ASIN原始数据'!L7,"")) | C7: =IF(OR(A7="",B7=""),"",IF(B7<='01_动态参数'!B15,1,0)) | D7: =IF(A7="","",IF(AND('02_ASIN原始数据'!D7>='01_动态参数'!B10,'02_ASIN原始数据'!D7<='01_动态参数'!B11),1,0)) | E7: =IF(A7="","",IF('02_ASIN原始数据'!N7>='01_动态参数'!B12,1,0)) | F7: =IF(A7="","",IF('02_ASIN原始数据'!J7>'01_动态参数'!B13,1,0)) | G7: =IF(A7="","",IF('02_ASIN原始数据'!F7>='01_动态参数'!B14,1,0)) | H7: =IF(A7="","",IF('02_ASIN原始数据'!M7="AMZ",1,0)) | I7: =IF(A7="","",IF('02_ASIN原始数据'!E7="", "",RANK('02_ASIN原始数据'!E7,'02_ASIN原始数据'!$E$3:$E$52,0))) | J7: =IF(A7="","",MIN(10,IF('02_ASIN原始数据'!J7<=300,10,IF('02_ASIN原始数据'!J7<=800,8,IF('02_ASIN原始数据'!J7<=1500,5,IF('02_ASIN原始数据'!J7<=3000,2,0))))+IF('02_ASIN原始数据'!P7<=3,2,0)+IF(I7<=10,1,0))) | K7: =IF(A7="","",MIN(10,IF('02_ASIN原始数据'!F7>=50,10,IF('02_ASIN原始数据'!F7>=30,9,IF('02_ASIN原始数据'!F7>=15,7,IF('02_ASIN原始数据'!F7>=5,5,2))))+IF(C7=1,2,0))) | L7: =IF(A7="","",IF(E7=0,0,IF(D7=1,8,3)+IF('02_ASIN原始数据'!N7>='01_动态参数'!B12+10,2,IF('02_ASIN原始数据'!N7>='01_动态参数'!B12,1,0)))) | M7: =IF(A7="","",MIN(10,IF('02_ASIN原始数据'!J7<=500,10,IF('02_ASIN原始数据'!J7<=1000,7,IF('02_ASIN原始数据'!J7<=2000,4,1)))+IF(C7=1,2,0)+IF(OR('02_ASIN原始数据'!Q7="Y",'02_ASIN原始数据'!Q7="Yes",'02_ASIN原始数据'!Q7="YES"),1,0))) | N7: 7
A8: ='02_ASIN原始数据'!A8 | B8: =IF('02_ASIN原始数据'!L8="","",IF(ISNUMBER('02_ASIN原始数据'!L8),TODAY()-'02_ASIN原始数据'!L8,"")) | C8: =IF(OR(A8="",B8=""),"",IF(B8<='01_动态参数'!B15,1,0)) | D8: =IF(A8="","",IF(AND('02_ASIN原始数据'!D8>='01_动态参数'!B10,'02_ASIN原始数据'!D8<='01_动态参数'!B11),1,0)) | E8: =IF(A8="","",IF('02_ASIN原始数据'!N8>='01_动态参数'!B12,1,0)) | F8: =IF(A8="","",IF('02_ASIN原始数据'!J8>'01_动态参数'!B13,1,0)) | G8: =IF(A8="","",IF('02_ASIN原始数据'!F8>='01_动态参数'!B14,1,0)) | H8: =IF(A8="","",IF('02_ASIN原始数据'!M8="AMZ",1,0)) | I8: =IF(A8="","",IF('02_ASIN原始数据'!E8="", "",RANK('02_ASIN原始数据'!E8,'02_ASIN原始数据'!$E$3:$E$52,0))) | J8: =IF(A8="","",MIN(10,IF('02_ASIN原始数据'!J8<=300,10,IF('02_ASIN原始数据'!J8<=800,8,IF('02_ASIN原始数据'!J8<=1500,5,IF('02_ASIN原始数据'!J8<=3000,2,0))))+IF('02_ASIN原始数据'!P8<=3,2,0)+IF(I8<=10,1,0))) | K8: =IF(A8="","",MIN(10,IF('02_ASIN原始数据'!F8>=50,10,IF('02_ASIN原始数据'!F8>=30,9,IF('02_ASIN原始数据'!F8>=15,7,IF('02_ASIN原始数据'!F8>=5,5,2))))+IF(C8=1,2,0))) | L8: =IF(A8="","",IF(E8=0,0,IF(D8=1,8,3)+IF('02_ASIN原始数据'!N8>='01_动态参数'!B12+10,2,IF('02_ASIN原始数据'!N8>='01_动态参数'!B12,1,0)))) | M8: =IF(A8="","",MIN(10,IF('02_ASIN原始数据'!J8<=500,10,IF('02_ASIN原始数据'!J8<=1000,7,IF('02_ASIN原始数据'!J8<=2000,4,1)))+IF(C8=1,2,0)+IF(OR('02_ASIN原始数据'!Q8="Y",'02_ASIN原始数据'!Q8="Yes",'02_ASIN原始数据'!Q8="YES"),1,0))) | N8: 8
A9: ='02_ASIN原始数据'!A9 | B9: =IF('02_ASIN原始数据'!L9="","",IF(ISNUMBER('02_ASIN原始数据'!L9),TODAY()-'02_ASIN原始数据'!L9,"")) | C9: =IF(OR(A9="",B9=""),"",IF(B9<='01_动态参数'!B15,1,0)) | D9: =IF(A9="","",IF(AND('02_ASIN原始数据'!D9>='01_动态参数'!B10,'02_ASIN原始数据'!D9<='01_动态参数'!B11),1,0)) | E9: =IF(A9="","",IF('02_ASIN原始数据'!N9>='01_动态参数'!B12,1,0)) | F9: =IF(A9="","",IF('02_ASIN原始数据'!J9>'01_动态参数'!B13,1,0)) | G9: =IF(A9="","",IF('02_ASIN原始数据'!F9>='01_动态参数'!B14,1,0)) | H9: =IF(A9="","",IF('02_ASIN原始数据'!M9="AMZ",1,0)) | I9: =IF(A9="","",IF('02_ASIN原始数据'!E9="", "",RANK('02_ASIN原始数据'!E9,'02_ASIN原始数据'!$E$3:$E$52,0))) | J9: =IF(A9="","",MIN(10,IF('02_ASIN原始数据'!J9<=300,10,IF('02_ASIN原始数据'!J9<=800,8,IF('02_ASIN原始数据'!J9<=1500,5,IF('02_ASIN原始数据'!J9<=3000,2,0))))+IF('02_ASIN原始数据'!P9<=3,2,0)+IF(I9<=10,1,0))) | K9: =IF(A9="","",MIN(10,IF('02_ASIN原始数据'!F9>=50,10,IF('02_ASIN原始数据'!F9>=30,9,IF('02_ASIN原始数据'!F9>=15,7,IF('02_ASIN原始数据'!F9>=5,5,2))))+IF(C9=1,2,0))) | L9: =IF(A9="","",IF(E9=0,0,IF(D9=1,8,3)+IF('02_ASIN原始数据'!N9>='01_动态参数'!B12+10,2,IF('02_ASIN原始数据'!N9>='01_动态参数'!B12,1,0)))) | M9: =IF(A9="","",MIN(10,IF('02_ASIN原始数据'!J9<=500,10,IF('02_ASIN原始数据'!J9<=1000,7,IF('02_ASIN原始数据'!J9<=2000,4,1)))+IF(C9=1,2,0)+IF(OR('02_ASIN原始数据'!Q9="Y",'02_ASIN原始数据'!Q9="Yes",'02_ASIN原始数据'!Q9="YES"),1,0))) | N9: 9
A10: ='02_ASIN原始数据'!A10 | B10: =IF('02_ASIN原始数据'!L10="","",IF(ISNUMBER('02_ASIN原始数据'!L10),TODAY()-'02_ASIN原始数据'!L10,"")) | C10: =IF(OR(A10="",B10=""),"",IF(B10<='01_动态参数'!B15,1,0)) | D10: =IF(A10="","",IF(AND('02_ASIN原始数据'!D10>='01_动态参数'!B10,'02_ASIN原始数据'!D10<='01_动态参数'!B11),1,0)) | E10: =IF(A10="","",IF('02_ASIN原始数据'!N10>='01_动态参数'!B12,1,0)) | F10: =IF(A10="","",IF('02_ASIN原始数据'!J10>'01_动态参数'!B13,1,0)) | G10: =IF(A10="","",IF('02_ASIN原始数据'!F10>='01_动态参数'!B14,1,0)) | H10: =IF(A10="","",IF('02_ASIN原始数据'!M10="AMZ",1,0)) | I10: =IF(A10="","",IF('02_ASIN原始数据'!E10="", "",RANK('02_ASIN原始数据'!E10,'02_ASIN原始数据'!$E$3:$E$52,0))) | J10: =IF(A10="","",MIN(10,IF('02_ASIN原始数据'!J10<=300,10,IF('02_ASIN原始数据'!J10<=800,8,IF('02_ASIN原始数据'!J10<=1500,5,IF('02_ASIN原始数据'!J10<=3000,2,0))))+IF('02_ASIN原始数据'!P10<=3,2,0)+IF(I10<=10,1,0))) | K10: =IF(A10="","",MIN(10,IF('02_ASIN原始数据'!F10>=50,10,IF('02_ASIN原始数据'!F10>=30,9,IF('02_ASIN原始数据'!F10>=15,7,IF('02_ASIN原始数据'!F10>=5,5,2))))+IF(C10=1,2,0))) | L10: =IF(A10="","",IF(E10=0,0,IF(D10=1,8,3)+IF('02_ASIN原始数据'!N10>='01_动态参数'!B12+10,2,IF('02_ASIN原始数据'!N10>='01_动态参数'!B12,1,0)))) | M10: =IF(A10="","",MIN(10,IF('02_ASIN原始数据'!J10<=500,10,IF('02_ASIN原始数据'!J10<=1000,7,IF('02_ASIN原始数据'!J10<=2000,4,1)))+IF(C10=1,2,0)+IF(OR('02_ASIN原始数据'!Q10="Y",'02_ASIN原始数据'!Q10="Yes",'02_ASIN原始数据'!Q10="YES"),1,0))) | N10: 10
A11: ='02_ASIN原始数据'!A11 | B11: =IF('02_ASIN原始数据'!L11="","",IF(ISNUMBER('02_ASIN原始数据'!L11),TODAY()-'02_ASIN原始数据'!L11,"")) | C11: =IF(OR(A11="",B11=""),"",IF(B11<='01_动态参数'!B15,1,0)) | D11: =IF(A11="","",IF(AND('02_ASIN原始数据'!D11>='01_动态参数'!B10,'02_ASIN原始数据'!D11<='01_动态参数'!B11),1,0)) | E11: =IF(A11="","",IF('02_ASIN原始数据'!N11>='01_动态参数'!B12,1,0)) | F11: =IF(A11="","",IF('02_ASIN原始数据'!J11>'01_动态参数'!B13,1,0)) | G11: =IF(A11="","",IF('02_ASIN原始数据'!F11>='01_动态参数'!B14,1,0)) | H11: =IF(A11="","",IF('02_ASIN原始数据'!M11="AMZ",1,0)) | I11: =IF(A11="","",IF('02_ASIN原始数据'!E11="", "",RANK('02_ASIN原始数据'!E11,'02_ASIN原始数据'!$E$3:$E$52,0))) | J11: =IF(A11="","",MIN(10,IF('02_ASIN原始数据'!J11<=300,10,IF('02_ASIN原始数据'!J11<=800,8,IF('02_ASIN原始数据'!J11<=1500,5,IF('02_ASIN原始数据'!J11<=3000,2,0))))+IF('02_ASIN原始数据'!P11<=3,2,0)+IF(I11<=10,1,0))) | K11: =IF(A11="","",MIN(10,IF('02_ASIN原始数据'!F11>=50,10,IF('02_ASIN原始数据'!F11>=30,9,IF('02_ASIN原始数据'!F11>=15,7,IF('02_ASIN原始数据'!F11>=5,5,2))))+IF(C11=1,2,0))) | L11: =IF(A11="","",IF(E11=0,0,IF(D11=1,8,3)+IF('02_ASIN原始数据'!N11>='01_动态参数'!B12+10,2,IF('02_ASIN原始数据'!N11>='01_动态参数'!B12,1,0)))) | M11: =IF(A11="","",MIN(10,IF('02_ASIN原始数据'!J11<=500,10,IF('02_ASIN原始数据'!J11<=1000,7,IF('02_ASIN原始数据'!J11<=2000,4,1)))+IF(C11=1,2,0)+IF(OR('02_ASIN原始数据'!Q11="Y",'02_ASIN原始数据'!Q11="Yes",'02_ASIN原始数据'!Q11="YES"),1,0))) | N11: 11
A12: ='02_ASIN原始数据'!A12 | B12: =IF('02_ASIN原始数据'!L12="","",IF(ISNUMBER('02_ASIN原始数据'!L12),TODAY()-'02_ASIN原始数据'!L12,"")) | C12: =IF(OR(A12="",B12=""),"",IF(B12<='01_动态参数'!B15,1,0)) | D12: =IF(A12="","",IF(AND('02_ASIN原始数据'!D12>='01_动态参数'!B10,'02_ASIN原始数据'!D12<='01_动态参数'!B11),1,0)) | E12: =IF(A12="","",IF('02_ASIN原始数据'!N12>='01_动态参数'!B12,1,0)) | F12: =IF(A12="","",IF('02_ASIN原始数据'!J12>'01_动态参数'!B13,1,0)) | G12: =IF(A12="","",IF('02_ASIN原始数据'!F12>='01_动态参数'!B14,1,0)) | H12: =IF(A12="","",IF('02_ASIN原始数据'!M12="AMZ",1,0)) | I12: =IF(A12="","",IF('02_ASIN原始数据'!E12="", "",RANK('02_ASIN原始数据'!E12,'02_ASIN原始数据'!$E$3:$E$52,0))) | J12: =IF(A12="","",MIN(10,IF('02_ASIN原始数据'!J12<=300,10,IF('02_ASIN原始数据'!J12<=800,8,IF('02_ASIN原始数据'!J12<=1500,5,IF('02_ASIN原始数据'!J12<=3000,2,0))))+IF('02_ASIN原始数据'!P12<=3,2,0)+IF(I12<=10,1,0))) | K12: =IF(A12="","",MIN(10,IF('02_ASIN原始数据'!F12>=50,10,IF('02_ASIN原始数据'!F12>=30,9,IF('02_ASIN原始数据'!F12>=15,7,IF('02_ASIN原始数据'!F12>=5,5,2))))+IF(C12=1,2,0))) | L12: =IF(A12="","",IF(E12=0,0,IF(D12=1,8,3)+IF('02_ASIN原始数据'!N12>='01_动态参数'!B12+10,2,IF('02_ASIN原始数据'!N12>='01_动态参数'!B12,1,0)))) | M12: =IF(A12="","",MIN(10,IF('02_ASIN原始数据'!J12<=500,10,IF('02_ASIN原始数据'!J12<=1000,7,IF('02_ASIN原始数据'!J12<=2000,4,1)))+IF(C12=1,2,0)+IF(OR('02_ASIN原始数据'!Q12="Y",'02_ASIN原始数据'!Q12="Yes",'02_ASIN原始数据'!Q12="YES"),1,0))) | N12: 12
A13: ='02_ASIN原始数据'!A13 | B13: =IF('02_ASIN原始数据'!L13="","",IF(ISNUMBER('02_ASIN原始数据'!L13),TODAY()-'02_ASIN原始数据'!L13,"")) | C13: =IF(OR(A13="",B13=""),"",IF(B13<='01_动态参数'!B15,1,0)) | D13: =IF(A13="","",IF(AND('02_ASIN原始数据'!D13>='01_动态参数'!B10,'02_ASIN原始数据'!D13<='01_动态参数'!B11),1,0)) | E13: =IF(A13="","",IF('02_ASIN原始数据'!N13>='01_动态参数'!B12,1,0)) | F13: =IF(A13="","",IF('02_ASIN原始数据'!J13>'01_动态参数'!B13,1,0)) | G13: =IF(A13="","",IF('02_ASIN原始数据'!F13>='01_动态参数'!B14,1,0)) | H13: =IF(A13="","",IF('02_ASIN原始数据'!M13="AMZ",1,0)) | I13: =IF(A13="","",IF('02_ASIN原始数据'!E13="", "",RANK('02_ASIN原始数据'!E13,'02_ASIN原始数据'!$E$3:$E$52,0))) | J13: =IF(A13="","",MIN(10,IF('02_ASIN原始数据'!J13<=300,10,IF('02_ASIN原始数据'!J13<=800,8,IF('02_ASIN原始数据'!J13<=1500,5,IF('02_ASIN原始数据'!J13<=3000,2,0))))+IF('02_ASIN原始数据'!P13<=3,2,0)+IF(I13<=10,1,0))) | K13: =IF(A13="","",MIN(10,IF('02_ASIN原始数据'!F13>=50,10,IF('02_ASIN原始数据'!F13>=30,9,IF('02_ASIN原始数据'!F13>=15,7,IF('02_ASIN原始数据'!F13>=5,5,2))))+IF(C13=1,2,0))) | L13: =IF(A13="","",IF(E13=0,0,IF(D13=1,8,3)+IF('02_ASIN原始数据'!N13>='01_动态参数'!B12+10,2,IF('02_ASIN原始数据'!N13>='01_动态参数'!B12,1,0)))) | M13: =IF(A13="","",MIN(10,IF('02_ASIN原始数据'!J13<=500,10,IF('02_ASIN原始数据'!J13<=1000,7,IF('02_ASIN原始数据'!J13<=2000,4,1)))+IF(C13=1,2,0)+IF(OR('02_ASIN原始数据'!Q13="Y",'02_ASIN原始数据'!Q13="Yes",'02_ASIN原始数据'!Q13="YES"),1,0))) | N13: 13
A14: ='02_ASIN原始数据'!A14 | B14: =IF('02_ASIN原始数据'!L14="","",IF(ISNUMBER('02_ASIN原始数据'!L14),TODAY()-'02_ASIN原始数据'!L14,"")) | C14: =IF(OR(A14="",B14=""),"",IF(B14<='01_动态参数'!B15,1,0)) | D14: =IF(A14="","",IF(AND('02_ASIN原始数据'!D14>='01_动态参数'!B10,'02_ASIN原始数据'!D14<='01_动态参数'!B11),1,0)) | E14: =IF(A14="","",IF('02_ASIN原始数据'!N14>='01_动态参数'!B12,1,0)) | F14: =IF(A14="","",IF('02_ASIN原始数据'!J14>'01_动态参数'!B13,1,0)) | G14: =IF(A14="","",IF('02_ASIN原始数据'!F14>='01_动态参数'!B14,1,0)) | H14: =IF(A14="","",IF('02_ASIN原始数据'!M14="AMZ",1,0)) | I14: =IF(A14="","",IF('02_ASIN原始数据'!E14="", "",RANK('02_ASIN原始数据'!E14,'02_ASIN原始数据'!$E$3:$E$52,0))) | J14: =IF(A14="","",MIN(10,IF('02_ASIN原始数据'!J14<=300,10,IF('02_ASIN原始数据'!J14<=800,8,IF('02_ASIN原始数据'!J14<=1500,5,IF('02_ASIN原始数据'!J14<=3000,2,0))))+IF('02_ASIN原始数据'!P14<=3,2,0)+IF(I14<=10,1,0))) | K14: =IF(A14="","",MIN(10,IF('02_ASIN原始数据'!F14>=50,10,IF('02_ASIN原始数据'!F14>=30,9,IF('02_ASIN原始数据'!F14>=15,7,IF('02_ASIN原始数据'!F14>=5,5,2))))+IF(C14=1,2,0))) | L14: =IF(A14="","",IF(E14=0,0,IF(D14=1,8,3)+IF('02_ASIN原始数据'!N14>='01_动态参数'!B12+10,2,IF('02_ASIN原始数据'!N14>='01_动态参数'!B12,1,0)))) | M14: =IF(A14="","",MIN(10,IF('02_ASIN原始数据'!J14<=500,10,IF('02_ASIN原始数据'!J14<=1000,7,IF('02_ASIN原始数据'!J14<=2000,4,1)))+IF(C14=1,2,0)+IF(OR('02_ASIN原始数据'!Q14="Y",'02_ASIN原始数据'!Q14="Yes",'02_ASIN原始数据'!Q14="YES"),1,0))) | N14: 14
A15: ='02_ASIN原始数据'!A15 | B15: =IF('02_ASIN原始数据'!L15="","",IF(ISNUMBER('02_ASIN原始数据'!L15),TODAY()-'02_ASIN原始数据'!L15,"")) | C15: =IF(OR(A15="",B15=""),"",IF(B15<='01_动态参数'!B15,1,0)) | D15: =IF(A15="","",IF(AND('02_ASIN原始数据'!D15>='01_动态参数'!B10,'02_ASIN原始数据'!D15<='01_动态参数'!B11),1,0)) | E15: =IF(A15="","",IF('02_ASIN原始数据'!N15>='01_动态参数'!B12,1,0)) | F15: =IF(A15="","",IF('02_ASIN原始数据'!J15>'01_动态参数'!B13,1,0)) | G15: =IF(A15="","",IF('02_ASIN原始数据'!F15>='01_动态参数'!B14,1,0)) | H15: =IF(A15="","",IF('02_ASIN原始数据'!M15="AMZ",1,0)) | I15: =IF(A15="","",IF('02_ASIN原始数据'!E15="", "",RANK('02_ASIN原始数据'!E15,'02_ASIN原始数据'!$E$3:$E$52,0))) | J15: =IF(A15="","",MIN(10,IF('02_ASIN原始数据'!J15<=300,10,IF('02_ASIN原始数据'!J15<=800,8,IF('02_ASIN原始数据'!J15<=1500,5,IF('02_ASIN原始数据'!J15<=3000,2,0))))+IF('02_ASIN原始数据'!P15<=3,2,0)+IF(I15<=10,1,0))) | K15: =IF(A15="","",MIN(10,IF('02_ASIN原始数据'!F15>=50,10,IF('02_ASIN原始数据'!F15>=30,9,IF('02_ASIN原始数据'!F15>=15,7,IF('02_ASIN原始数据'!F15>=5,5,2))))+IF(C15=1,2,0))) | L15: =IF(A15="","",IF(E15=0,0,IF(D15=1,8,3)+IF('02_ASIN原始数据'!N15>='01_动态参数'!B12+10,2,IF('02_ASIN原始数据'!N15>='01_动态参数'!B12,1,0)))) | M15: =IF(A15="","",MIN(10,IF('02_ASIN原始数据'!J15<=500,10,IF('02_ASIN原始数据'!J15<=1000,7,IF('02_ASIN原始数据'!J15<=2000,4,1)))+IF(C15=1,2,0)+IF(OR('02_ASIN原始数据'!Q15="Y",'02_ASIN原始数据'!Q15="Yes",'02_ASIN原始数据'!Q15="YES"),1,0))) | N15: 15
A16: ='02_ASIN原始数据'!A16 | B16: =IF('02_ASIN原始数据'!L16="","",IF(ISNUMBER('02_ASIN原始数据'!L16),TODAY()-'02_ASIN原始数据'!L16,"")) | C16: =IF(OR(A16="",B16=""),"",IF(B16<='01_动态参数'!B15,1,0)) | D16: =IF(A16="","",IF(AND('02_ASIN原始数据'!D16>='01_动态参数'!B10,'02_ASIN原始数据'!D16<='01_动态参数'!B11),1,0)) | E16: =IF(A16="","",IF('02_ASIN原始数据'!N16>='01_动态参数'!B12,1,0)) | F16: =IF(A16="","",IF('02_ASIN原始数据'!J16>'01_动态参数'!B13,1,0)) | G16: =IF(A16="","",IF('02_ASIN原始数据'!F16>='01_动态参数'!B14,1,0)) | H16: =IF(A16="","",IF('02_ASIN原始数据'!M16="AMZ",1,0)) | I16: =IF(A16="","",IF('02_ASIN原始数据'!E16="", "",RANK('02_ASIN原始数据'!E16,'02_ASIN原始数据'!$E$3:$E$52,0))) | J16: =IF(A16="","",MIN(10,IF('02_ASIN原始数据'!J16<=300,10,IF('02_ASIN原始数据'!J16<=800,8,IF('02_ASIN原始数据'!J16<=1500,5,IF('02_ASIN原始数据'!J16<=3000,2,0))))+IF('02_ASIN原始数据'!P16<=3,2,0)+IF(I16<=10,1,0))) | K16: =IF(A16="","",MIN(10,IF('02_ASIN原始数据'!F16>=50,10,IF('02_ASIN原始数据'!F16>=30,9,IF('02_ASIN原始数据'!F16>=15,7,IF('02_ASIN原始数据'!F16>=5,5,2))))+IF(C16=1,2,0))) | L16: =IF(A16="","",IF(E16=0,0,IF(D16=1,8,3)+IF('02_ASIN原始数据'!N16>='01_动态参数'!B12+10,2,IF('02_ASIN原始数据'!N16>='01_动态参数'!B12,1,0)))) | M16: =IF(A16="","",MIN(10,IF('02_ASIN原始数据'!J16<=500,10,IF('02_ASIN原始数据'!J16<=1000,7,IF('02_ASIN原始数据'!J16<=2000,4,1)))+IF(C16=1,2,0)+IF(OR('02_ASIN原始数据'!Q16="Y",'02_ASIN原始数据'!Q16="Yes",'02_ASIN原始数据'!Q16="YES"),1,0))) | N16: 16
A17: ='02_ASIN原始数据'!A17 | B17: =IF('02_ASIN原始数据'!L17="","",IF(ISNUMBER('02_ASIN原始数据'!L17),TODAY()-'02_ASIN原始数据'!L17,"")) | C17: =IF(OR(A17="",B17=""),"",IF(B17<='01_动态参数'!B15,1,0)) | D17: =IF(A17="","",IF(AND('02_ASIN原始数据'!D17>='01_动态参数'!B10,'02_ASIN原始数据'!D17<='01_动态参数'!B11),1,0)) | E17: =IF(A17="","",IF('02_ASIN原始数据'!N17>='01_动态参数'!B12,1,0)) | F17: =IF(A17="","",IF('02_ASIN原始数据'!J17>'01_动态参数'!B13,1,0)) | G17: =IF(A17="","",IF('02_ASIN原始数据'!F17>='01_动态参数'!B14,1,0)) | H17: =IF(A17="","",IF('02_ASIN原始数据'!M17="AMZ",1,0)) | I17: =IF(A17="","",IF('02_ASIN原始数据'!E17="", "",RANK('02_ASIN原始数据'!E17,'02_ASIN原始数据'!$E$3:$E$52,0))) | J17: =IF(A17="","",MIN(10,IF('02_ASIN原始数据'!J17<=300,10,IF('02_ASIN原始数据'!J17<=800,8,IF('02_ASIN原始数据'!J17<=1500,5,IF('02_ASIN原始数据'!J17<=3000,2,0))))+IF('02_ASIN原始数据'!P17<=3,2,0)+IF(I17<=10,1,0))) | K17: =IF(A17="","",MIN(10,IF('02_ASIN原始数据'!F17>=50,10,IF('02_ASIN原始数据'!F17>=30,9,IF('02_ASIN原始数据'!F17>=15,7,IF('02_ASIN原始数据'!F17>=5,5,2))))+IF(C17=1,2,0))) | L17: =IF(A17="","",IF(E17=0,0,IF(D17=1,8,3)+IF('02_ASIN原始数据'!N17>='01_动态参数'!B12+10,2,IF('02_ASIN原始数据'!N17>='01_动态参数'!B12,1,0)))) | M17: =IF(A17="","",MIN(10,IF('02_ASIN原始数据'!J17<=500,10,IF('02_ASIN原始数据'!J17<=1000,7,IF('02_ASIN原始数据'!J17<=2000,4,1)))+IF(C17=1,2,0)+IF(OR('02_ASIN原始数据'!Q17="Y",'02_ASIN原始数据'!Q17="Yes",'02_ASIN原始数据'!Q17="YES"),1,0))) | N17: 17
A18: ='02_ASIN原始数据'!A18 | B18: =IF('02_ASIN原始数据'!L18="","",IF(ISNUMBER('02_ASIN原始数据'!L18),TODAY()-'02_ASIN原始数据'!L18,"")) | C18: =IF(OR(A18="",B18=""),"",IF(B18<='01_动态参数'!B15,1,0)) | D18: =IF(A18="","",IF(AND('02_ASIN原始数据'!D18>='01_动态参数'!B10,'02_ASIN原始数据'!D18<='01_动态参数'!B11),1,0)) | E18: =IF(A18="","",IF('02_ASIN原始数据'!N18>='01_动态参数'!B12,1,0)) | F18: =IF(A18="","",IF('02_ASIN原始数据'!J18>'01_动态参数'!B13,1,0)) | G18: =IF(A18="","",IF('02_ASIN原始数据'!F18>='01_动态参数'!B14,1,0)) | H18: =IF(A18="","",IF('02_ASIN原始数据'!M18="AMZ",1,0)) | I18: =IF(A18="","",IF('02_ASIN原始数据'!E18="", "",RANK('02_ASIN原始数据'!E18,'02_ASIN原始数据'!$E$3:$E$52,0))) | J18: =IF(A18="","",MIN(10,IF('02_ASIN原始数据'!J18<=300,10,IF('02_ASIN原始数据'!J18<=800,8,IF('02_ASIN原始数据'!J18<=1500,5,IF('02_ASIN原始数据'!J18<=3000,2,0))))+IF('02_ASIN原始数据'!P18<=3,2,0)+IF(I18<=10,1,0))) | K18: =IF(A18="","",MIN(10,IF('02_ASIN原始数据'!F18>=50,10,IF('02_ASIN原始数据'!F18>=30,9,IF('02_ASIN原始数据'!F18>=15,7,IF('02_ASIN原始数据'!F18>=5,5,2))))+IF(C18=1,2,0))) | L18: =IF(A18="","",IF(E18=0,0,IF(D18=1,8,3)+IF('02_ASIN原始数据'!N18>='01_动态参数'!B12+10,2,IF('02_ASIN原始数据'!N18>='01_动态参数'!B12,1,0)))) | M18: =IF(A18="","",MIN(10,IF('02_ASIN原始数据'!J18<=500,10,IF('02_ASIN原始数据'!J18<=1000,7,IF('02_ASIN原始数据'!J18<=2000,4,1)))+IF(C18=1,2,0)+IF(OR('02_ASIN原始数据'!Q18="Y",'02_ASIN原始数据'!Q18="Yes",'02_ASIN原始数据'!Q18="YES"),1,0))) | N18: 18
A19: ='02_ASIN原始数据'!A19 | B19: =IF('02_ASIN原始数据'!L19="","",IF(ISNUMBER('02_ASIN原始数据'!L19),TODAY()-'02_ASIN原始数据'!L19,"")) | C19: =IF(OR(A19="",B19=""),"",IF(B19<='01_动态参数'!B15,1,0)) | D19: =IF(A19="","",IF(AND('02_ASIN原始数据'!D19>='01_动态参数'!B10,'02_ASIN原始数据'!D19<='01_动态参数'!B11),1,0)) | E19: =IF(A19="","",IF('02_ASIN原始数据'!N19>='01_动态参数'!B12,1,0)) | F19: =IF(A19="","",IF('02_ASIN原始数据'!J19>'01_动态参数'!B13,1,0)) | G19: =IF(A19="","",IF('02_ASIN原始数据'!F19>='01_动态参数'!B14,1,0)) | H19: =IF(A19="","",IF('02_ASIN原始数据'!M19="AMZ",1,0)) | I19: =IF(A19="","",IF('02_ASIN原始数据'!E19="", "",RANK('02_ASIN原始数据'!E19,'02_ASIN原始数据'!$E$3:$E$52,0))) | J19: =IF(A19="","",MIN(10,IF('02_ASIN原始数据'!J19<=300,10,IF('02_ASIN原始数据'!J19<=800,8,IF('02_ASIN原始数据'!J19<=1500,5,IF('02_ASIN原始数据'!J19<=3000,2,0))))+IF('02_ASIN原始数据'!P19<=3,2,0)+IF(I19<=10,1,0))) | K19: =IF(A19="","",MIN(10,IF('02_ASIN原始数据'!F19>=50,10,IF('02_ASIN原始数据'!F19>=30,9,IF('02_ASIN原始数据'!F19>=15,7,IF('02_ASIN原始数据'!F19>=5,5,2))))+IF(C19=1,2,0))) | L19: =IF(A19="","",IF(E19=0,0,IF(D19=1,8,3)+IF('02_ASIN原始数据'!N19>='01_动态参数'!B12+10,2,IF('02_ASIN原始数据'!N19>='01_动态参数'!B12,1,0)))) | M19: =IF(A19="","",MIN(10,IF('02_ASIN原始数据'!J19<=500,10,IF('02_ASIN原始数据'!J19<=1000,7,IF('02_ASIN原始数据'!J19<=2000,4,1)))+IF(C19=1,2,0)+IF(OR('02_ASIN原始数据'!Q19="Y",'02_ASIN原始数据'!Q19="Yes",'02_ASIN原始数据'!Q19="YES"),1,0))) | N19: 19
A20: ='02_ASIN原始数据'!A20 | B20: =IF('02_ASIN原始数据'!L20="","",IF(ISNUMBER('02_ASIN原始数据'!L20),TODAY()-'02_ASIN原始数据'!L20,"")) | C20: =IF(OR(A20="",B20=""),"",IF(B20<='01_动态参数'!B15,1,0)) | D20: =IF(A20="","",IF(AND('02_ASIN原始数据'!D20>='01_动态参数'!B10,'02_ASIN原始数据'!D20<='01_动态参数'!B11),1,0)) | E20: =IF(A20="","",IF('02_ASIN原始数据'!N20>='01_动态参数'!B12,1,0)) | F20: =IF(A20="","",IF('02_ASIN原始数据'!J20>'01_动态参数'!B13,1,0)) | G20: =IF(A20="","",IF('02_ASIN原始数据'!F20>='01_动态参数'!B14,1,0)) | H20: =IF(A20="","",IF('02_ASIN原始数据'!M20="AMZ",1,0)) | I20: =IF(A20="","",IF('02_ASIN原始数据'!E20="", "",RANK('02_ASIN原始数据'!E20,'02_ASIN原始数据'!$E$3:$E$52,0))) | J20: =IF(A20="","",MIN(10,IF('02_ASIN原始数据'!J20<=300,10,IF('02_ASIN原始数据'!J20<=800,8,IF('02_ASIN原始数据'!J20<=1500,5,IF('02_ASIN原始数据'!J20<=3000,2,0))))+IF('02_ASIN原始数据'!P20<=3,2,0)+IF(I20<=10,1,0))) | K20: =IF(A20="","",MIN(10,IF('02_ASIN原始数据'!F20>=50,10,IF('02_ASIN原始数据'!F20>=30,9,IF('02_ASIN原始数据'!F20>=15,7,IF('02_ASIN原始数据'!F20>=5,5,2))))+IF(C20=1,2,0))) | L20: =IF(A20="","",IF(E20=0,0,IF(D20=1,8,3)+IF('02_ASIN原始数据'!N20>='01_动态参数'!B12+10,2,IF('02_ASIN原始数据'!N20>='01_动态参数'!B12,1,0)))) | M20: =IF(A20="","",MIN(10,IF('02_ASIN原始数据'!J20<=500,10,IF('02_ASIN原始数据'!J20<=1000,7,IF('02_ASIN原始数据'!J20<=2000,4,1)))+IF(C20=1,2,0)+IF(OR('02_ASIN原始数据'!Q20="Y",'02_ASIN原始数据'!Q20="Yes",'02_ASIN原始数据'!Q20="YES"),1,0))) | N20: 20
A21: ='02_ASIN原始数据'!A21 | B21: =IF('02_ASIN原始数据'!L21="","",IF(ISNUMBER('02_ASIN原始数据'!L21),TODAY()-'02_ASIN原始数据'!L21,"")) | C21: =IF(OR(A21="",B21=""),"",IF(B21<='01_动态参数'!B15,1,0)) | D21: =IF(A21="","",IF(AND('02_ASIN原始数据'!D21>='01_动态参数'!B10,'02_ASIN原始数据'!D21<='01_动态参数'!B11),1,0)) | E21: =IF(A21="","",IF('02_ASIN原始数据'!N21>='01_动态参数'!B12,1,0)) | F21: =IF(A21="","",IF('02_ASIN原始数据'!J21>'01_动态参数'!B13,1,0)) | G21: =IF(A21="","",IF('02_ASIN原始数据'!F21>='01_动态参数'!B14,1,0)) | H21: =IF(A21="","",IF('02_ASIN原始数据'!M21="AMZ",1,0)) | I21: =IF(A21="","",IF('02_ASIN原始数据'!E21="", "",RANK('02_ASIN原始数据'!E21,'02_ASIN原始数据'!$E$3:$E$52,0))) | J21: =IF(A21="","",MIN(10,IF('02_ASIN原始数据'!J21<=300,10,IF('02_ASIN原始数据'!J21<=800,8,IF('02_ASIN原始数据'!J21<=1500,5,IF('02_ASIN原始数据'!J21<=3000,2,0))))+IF('02_ASIN原始数据'!P21<=3,2,0)+IF(I21<=10,1,0))) | K21: =IF(A21="","",MIN(10,IF('02_ASIN原始数据'!F21>=50,10,IF('02_ASIN原始数据'!F21>=30,9,IF('02_ASIN原始数据'!F21>=15,7,IF('02_ASIN原始数据'!F21>=5,5,2))))+IF(C21=1,2,0))) | L21: =IF(A21="","",IF(E21=0,0,IF(D21=1,8,3)+IF('02_ASIN原始数据'!N21>='01_动态参数'!B12+10,2,IF('02_ASIN原始数据'!N21>='01_动态参数'!B12,1,0)))) | M21: =IF(A21="","",MIN(10,IF('02_ASIN原始数据'!J21<=500,10,IF('02_ASIN原始数据'!J21<=1000,7,IF('02_ASIN原始数据'!J21<=2000,4,1)))+IF(C21=1,2,0)+IF(OR('02_ASIN原始数据'!Q21="Y",'02_ASIN原始数据'!Q21="Yes",'02_ASIN原始数据'!Q21="YES"),1,0))) | N21: 21
A22: ='02_ASIN原始数据'!A22 | B22: =IF('02_ASIN原始数据'!L22="","",IF(ISNUMBER('02_ASIN原始数据'!L22),TODAY()-'02_ASIN原始数据'!L22,"")) | C22: =IF(OR(A22="",B22=""),"",IF(B22<='01_动态参数'!B15,1,0)) | D22: =IF(A22="","",IF(AND('02_ASIN原始数据'!D22>='01_动态参数'!B10,'02_ASIN原始数据'!D22<='01_动态参数'!B11),1,0)) | E22: =IF(A22="","",IF('02_ASIN原始数据'!N22>='01_动态参数'!B12,1,0)) | F22: =IF(A22="","",IF('02_ASIN原始数据'!J22>'01_动态参数'!B13,1,0)) | G22: =IF(A22="","",IF('02_ASIN原始数据'!F22>='01_动态参数'!B14,1,0)) | H22: =IF(A22="","",IF('02_ASIN原始数据'!M22="AMZ",1,0)) | I22: =IF(A22="","",IF('02_ASIN原始数据'!E22="", "",RANK('02_ASIN原始数据'!E22,'02_ASIN原始数据'!$E$3:$E$52,0))) | J22: =IF(A22="","",MIN(10,IF('02_ASIN原始数据'!J22<=300,10,IF('02_ASIN原始数据'!J22<=800,8,IF('02_ASIN原始数据'!J22<=1500,5,IF('02_ASIN原始数据'!J22<=3000,2,0))))+IF('02_ASIN原始数据'!P22<=3,2,0)+IF(I22<=10,1,0))) | K22: =IF(A22="","",MIN(10,IF('02_ASIN原始数据'!F22>=50,10,IF('02_ASIN原始数据'!F22>=30,9,IF('02_ASIN原始数据'!F22>=15,7,IF('02_ASIN原始数据'!F22>=5,5,2))))+IF(C22=1,2,0))) | L22: =IF(A22="","",IF(E22=0,0,IF(D22=1,8,3)+IF('02_ASIN原始数据'!N22>='01_动态参数'!B12+10,2,IF('02_ASIN原始数据'!N22>='01_动态参数'!B12,1,0)))) | M22: =IF(A22="","",MIN(10,IF('02_ASIN原始数据'!J22<=500,10,IF('02_ASIN原始数据'!J22<=1000,7,IF('02_ASIN原始数据'!J22<=2000,4,1)))+IF(C22=1,2,0)+IF(OR('02_ASIN原始数据'!Q22="Y",'02_ASIN原始数据'!Q22="Yes",'02_ASIN原始数据'!Q22="YES"),1,0))) | N22: 22
A23: ='02_ASIN原始数据'!A23 | B23: =IF('02_ASIN原始数据'!L23="","",IF(ISNUMBER('02_ASIN原始数据'!L23),TODAY()-'02_ASIN原始数据'!L23,"")) | C23: =IF(OR(A23="",B23=""),"",IF(B23<='01_动态参数'!B15,1,0)) | D23: =IF(A23="","",IF(AND('02_ASIN原始数据'!D23>='01_动态参数'!B10,'02_ASIN原始数据'!D23<='01_动态参数'!B11),1,0)) | E23: =IF(A23="","",IF('02_ASIN原始数据'!N23>='01_动态参数'!B12,1,0)) | F23: =IF(A23="","",IF('02_ASIN原始数据'!J23>'01_动态参数'!B13,1,0)) | G23: =IF(A23="","",IF('02_ASIN原始数据'!F23>='01_动态参数'!B14,1,0)) | H23: =IF(A23="","",IF('02_ASIN原始数据'!M23="AMZ",1,0)) | I23: =IF(A23="","",IF('02_ASIN原始数据'!E23="", "",RANK('02_ASIN原始数据'!E23,'02_ASIN原始数据'!$E$3:$E$52,0))) | J23: =IF(A23="","",MIN(10,IF('02_ASIN原始数据'!J23<=300,10,IF('02_ASIN原始数据'!J23<=800,8,IF('02_ASIN原始数据'!J23<=1500,5,IF('02_ASIN原始数据'!J23<=3000,2,0))))+IF('02_ASIN原始数据'!P23<=3,2,0)+IF(I23<=10,1,0))) | K23: =IF(A23="","",MIN(10,IF('02_ASIN原始数据'!F23>=50,10,IF('02_ASIN原始数据'!F23>=30,9,IF('02_ASIN原始数据'!F23>=15,7,IF('02_ASIN原始数据'!F23>=5,5,2))))+IF(C23=1,2,0))) | L23: =IF(A23="","",IF(E23=0,0,IF(D23=1,8,3)+IF('02_ASIN原始数据'!N23>='01_动态参数'!B12+10,2,IF('02_ASIN原始数据'!N23>='01_动态参数'!B12,1,0)))) | M23: =IF(A23="","",MIN(10,IF('02_ASIN原始数据'!J23<=500,10,IF('02_ASIN原始数据'!J23<=1000,7,IF('02_ASIN原始数据'!J23<=2000,4,1)))+IF(C23=1,2,0)+IF(OR('02_ASIN原始数据'!Q23="Y",'02_ASIN原始数据'!Q23="Yes",'02_ASIN原始数据'!Q23="YES"),1,0))) | N23: 23
A24: ='02_ASIN原始数据'!A24 | B24: =IF('02_ASIN原始数据'!L24="","",IF(ISNUMBER('02_ASIN原始数据'!L24),TODAY()-'02_ASIN原始数据'!L24,"")) | C24: =IF(OR(A24="",B24=""),"",IF(B24<='01_动态参数'!B15,1,0)) | D24: =IF(A24="","",IF(AND('02_ASIN原始数据'!D24>='01_动态参数'!B10,'02_ASIN原始数据'!D24<='01_动态参数'!B11),1,0)) | E24: =IF(A24="","",IF('02_ASIN原始数据'!N24>='01_动态参数'!B12,1,0)) | F24: =IF(A24="","",IF('02_ASIN原始数据'!J24>'01_动态参数'!B13,1,0)) | G24: =IF(A24="","",IF('02_ASIN原始数据'!F24>='01_动态参数'!B14,1,0)) | H24: =IF(A24="","",IF('02_ASIN原始数据'!M24="AMZ",1,0)) | I24: =IF(A24="","",IF('02_ASIN原始数据'!E24="", "",RANK('02_ASIN原始数据'!E24,'02_ASIN原始数据'!$E$3:$E$52,0))) | J24: =IF(A24="","",MIN(10,IF('02_ASIN原始数据'!J24<=300,10,IF('02_ASIN原始数据'!J24<=800,8,IF('02_ASIN原始数据'!J24<=1500,5,IF('02_ASIN原始数据'!J24<=3000,2,0))))+IF('02_ASIN原始数据'!P24<=3,2,0)+IF(I24<=10,1,0))) | K24: =IF(A24="","",MIN(10,IF('02_ASIN原始数据'!F24>=50,10,IF('02_ASIN原始数据'!F24>=30,9,IF('02_ASIN原始数据'!F24>=15,7,IF('02_ASIN原始数据'!F24>=5,5,2))))+IF(C24=1,2,0))) | L24: =IF(A24="","",IF(E24=0,0,IF(D24=1,8,3)+IF('02_ASIN原始数据'!N24>='01_动态参数'!B12+10,2,IF('02_ASIN原始数据'!N24>='01_动态参数'!B12,1,0)))) | M24: =IF(A24="","",MIN(10,IF('02_ASIN原始数据'!J24<=500,10,IF('02_ASIN原始数据'!J24<=1000,7,IF('02_ASIN原始数据'!J24<=2000,4,1)))+IF(C24=1,2,0)+IF(OR('02_ASIN原始数据'!Q24="Y",'02_ASIN原始数据'!Q24="Yes",'02_ASIN原始数据'!Q24="YES"),1,0))) | N24: 24
A25: ='02_ASIN原始数据'!A25 | B25: =IF('02_ASIN原始数据'!L25="","",IF(ISNUMBER('02_ASIN原始数据'!L25),TODAY()-'02_ASIN原始数据'!L25,"")) | C25: =IF(OR(A25="",B25=""),"",IF(B25<='01_动态参数'!B15,1,0)) | D25: =IF(A25="","",IF(AND('02_ASIN原始数据'!D25>='01_动态参数'!B10,'02_ASIN原始数据'!D25<='01_动态参数'!B11),1,0)) | E25: =IF(A25="","",IF('02_ASIN原始数据'!N25>='01_动态参数'!B12,1,0)) | F25: =IF(A25="","",IF('02_ASIN原始数据'!J25>'01_动态参数'!B13,1,0)) | G25: =IF(A25="","",IF('02_ASIN原始数据'!F25>='01_动态参数'!B14,1,0)) | H25: =IF(A25="","",IF('02_ASIN原始数据'!M25="AMZ",1,0)) | I25: =IF(A25="","",IF('02_ASIN原始数据'!E25="", "",RANK('02_ASIN原始数据'!E25,'02_ASIN原始数据'!$E$3:$E$52,0))) | J25: =IF(A25="","",MIN(10,IF('02_ASIN原始数据'!J25<=300,10,IF('02_ASIN原始数据'!J25<=800,8,IF('02_ASIN原始数据'!J25<=1500,5,IF('02_ASIN原始数据'!J25<=3000,2,0))))+IF('02_ASIN原始数据'!P25<=3,2,0)+IF(I25<=10,1,0))) | K25: =IF(A25="","",MIN(10,IF('02_ASIN原始数据'!F25>=50,10,IF('02_ASIN原始数据'!F25>=30,9,IF('02_ASIN原始数据'!F25>=15,7,IF('02_ASIN原始数据'!F25>=5,5,2))))+IF(C25=1,2,0))) | L25: =IF(A25="","",IF(E25=0,0,IF(D25=1,8,3)+IF('02_ASIN原始数据'!N25>='01_动态参数'!B12+10,2,IF('02_ASIN原始数据'!N25>='01_动态参数'!B12,1,0)))) | M25: =IF(A25="","",MIN(10,IF('02_ASIN原始数据'!J25<=500,10,IF('02_ASIN原始数据'!J25<=1000,7,IF('02_ASIN原始数据'!J25<=2000,4,1)))+IF(C25=1,2,0)+IF(OR('02_ASIN原始数据'!Q25="Y",'02_ASIN原始数据'!Q25="Yes",'02_ASIN原始数据'!Q25="YES"),1,0))) | N25: 25
A26: ='02_ASIN原始数据'!A26 | B26: =IF('02_ASIN原始数据'!L26="","",IF(ISNUMBER('02_ASIN原始数据'!L26),TODAY()-'02_ASIN原始数据'!L26,"")) | C26: =IF(OR(A26="",B26=""),"",IF(B26<='01_动态参数'!B15,1,0)) | D26: =IF(A26="","",IF(AND('02_ASIN原始数据'!D26>='01_动态参数'!B10,'02_ASIN原始数据'!D26<='01_动态参数'!B11),1,0)) | E26: =IF(A26="","",IF('02_ASIN原始数据'!N26>='01_动态参数'!B12,1,0)) | F26: =IF(A26="","",IF('02_ASIN原始数据'!J26>'01_动态参数'!B13,1,0)) | G26: =IF(A26="","",IF('02_ASIN原始数据'!F26>='01_动态参数'!B14,1,0)) | H26: =IF(A26="","",IF('02_ASIN原始数据'!M26="AMZ",1,0)) | I26: =IF(A26="","",IF('02_ASIN原始数据'!E26="", "",RANK('02_ASIN原始数据'!E26,'02_ASIN原始数据'!$E$3:$E$52,0))) | J26: =IF(A26="","",MIN(10,IF('02_ASIN原始数据'!J26<=300,10,IF('02_ASIN原始数据'!J26<=800,8,IF('02_ASIN原始数据'!J26<=1500,5,IF('02_ASIN原始数据'!J26<=3000,2,0))))+IF('02_ASIN原始数据'!P26<=3,2,0)+IF(I26<=10,1,0))) | K26: =IF(A26="","",MIN(10,IF('02_ASIN原始数据'!F26>=50,10,IF('02_ASIN原始数据'!F26>=30,9,IF('02_ASIN原始数据'!F26>=15,7,IF('02_ASIN原始数据'!F26>=5,5,2))))+IF(C26=1,2,0))) | L26: =IF(A26="","",IF(E26=0,0,IF(D26=1,8,3)+IF('02_ASIN原始数据'!N26>='01_动态参数'!B12+10,2,IF('02_ASIN原始数据'!N26>='01_动态参数'!B12,1,0)))) | M26: =IF(A26="","",MIN(10,IF('02_ASIN原始数据'!J26<=500,10,IF('02_ASIN原始数据'!J26<=1000,7,IF('02_ASIN原始数据'!J26<=2000,4,1)))+IF(C26=1,2,0)+IF(OR('02_ASIN原始数据'!Q26="Y",'02_ASIN原始数据'!Q26="Yes",'02_ASIN原始数据'!Q26="YES"),1,0))) | N26: 26
A27: ='02_ASIN原始数据'!A27 | B27: =IF('02_ASIN原始数据'!L27="","",IF(ISNUMBER('02_ASIN原始数据'!L27),TODAY()-'02_ASIN原始数据'!L27,"")) | C27: =IF(OR(A27="",B27=""),"",IF(B27<='01_动态参数'!B15,1,0)) | D27: =IF(A27="","",IF(AND('02_ASIN原始数据'!D27>='01_动态参数'!B10,'02_ASIN原始数据'!D27<='01_动态参数'!B11),1,0)) | E27: =IF(A27="","",IF('02_ASIN原始数据'!N27>='01_动态参数'!B12,1,0)) | F27: =IF(A27="","",IF('02_ASIN原始数据'!J27>'01_动态参数'!B13,1,0)) | G27: =IF(A27="","",IF('02_ASIN原始数据'!F27>='01_动态参数'!B14,1,0)) | H27: =IF(A27="","",IF('02_ASIN原始数据'!M27="AMZ",1,0)) | I27: =IF(A27="","",IF('02_ASIN原始数据'!E27="", "",RANK('02_ASIN原始数据'!E27,'02_ASIN原始数据'!$E$3:$E$52,0))) | J27: =IF(A27="","",MIN(10,IF('02_ASIN原始数据'!J27<=300,10,IF('02_ASIN原始数据'!J27<=800,8,IF('02_ASIN原始数据'!J27<=1500,5,IF('02_ASIN原始数据'!J27<=3000,2,0))))+IF('02_ASIN原始数据'!P27<=3,2,0)+IF(I27<=10,1,0))) | K27: =IF(A27="","",MIN(10,IF('02_ASIN原始数据'!F27>=50,10,IF('02_ASIN原始数据'!F27>=30,9,IF('02_ASIN原始数据'!F27>=15,7,IF('02_ASIN原始数据'!F27>=5,5,2))))+IF(C27=1,2,0))) | L27: =IF(A27="","",IF(E27=0,0,IF(D27=1,8,3)+IF('02_ASIN原始数据'!N27>='01_动态参数'!B12+10,2,IF('02_ASIN原始数据'!N27>='01_动态参数'!B12,1,0)))) | M27: =IF(A27="","",MIN(10,IF('02_ASIN原始数据'!J27<=500,10,IF('02_ASIN原始数据'!J27<=1000,7,IF('02_ASIN原始数据'!J27<=2000,4,1)))+IF(C27=1,2,0)+IF(OR('02_ASIN原始数据'!Q27="Y",'02_ASIN原始数据'!Q27="Yes",'02_ASIN原始数据'!Q27="YES"),1,0))) | N27: 27
A28: ='02_ASIN原始数据'!A28 | B28: =IF('02_ASIN原始数据'!L28="","",IF(ISNUMBER('02_ASIN原始数据'!L28),TODAY()-'02_ASIN原始数据'!L28,"")) | C28: =IF(OR(A28="",B28=""),"",IF(B28<='01_动态参数'!B15,1,0)) | D28: =IF(A28="","",IF(AND('02_ASIN原始数据'!D28>='01_动态参数'!B10,'02_ASIN原始数据'!D28<='01_动态参数'!B11),1,0)) | E28: =IF(A28="","",IF('02_ASIN原始数据'!N28>='01_动态参数'!B12,1,0)) | F28: =IF(A28="","",IF('02_ASIN原始数据'!J28>'01_动态参数'!B13,1,0)) | G28: =IF(A28="","",IF('02_ASIN原始数据'!F28>='01_动态参数'!B14,1,0)) | H28: =IF(A28="","",IF('02_ASIN原始数据'!M28="AMZ",1,0)) | I28: =IF(A28="","",IF('02_ASIN原始数据'!E28="", "",RANK('02_ASIN原始数据'!E28,'02_ASIN原始数据'!$E$3:$E$52,0))) | J28: =IF(A28="","",MIN(10,IF('02_ASIN原始数据'!J28<=300,10,IF('02_ASIN原始数据'!J28<=800,8,IF('02_ASIN原始数据'!J28<=1500,5,IF('02_ASIN原始数据'!J28<=3000,2,0))))+IF('02_ASIN原始数据'!P28<=3,2,0)+IF(I28<=10,1,0))) | K28: =IF(A28="","",MIN(10,IF('02_ASIN原始数据'!F28>=50,10,IF('02_ASIN原始数据'!F28>=30,9,IF('02_ASIN原始数据'!F28>=15,7,IF('02_ASIN原始数据'!F28>=5,5,2))))+IF(C28=1,2,0))) | L28: =IF(A28="","",IF(E28=0,0,IF(D28=1,8,3)+IF('02_ASIN原始数据'!N28>='01_动态参数'!B12+10,2,IF('02_ASIN原始数据'!N28>='01_动态参数'!B12,1,0)))) | M28: =IF(A28="","",MIN(10,IF('02_ASIN原始数据'!J28<=500,10,IF('02_ASIN原始数据'!J28<=1000,7,IF('02_ASIN原始数据'!J28<=2000,4,1)))+IF(C28=1,2,0)+IF(OR('02_ASIN原始数据'!Q28="Y",'02_ASIN原始数据'!Q28="Yes",'02_ASIN原始数据'!Q28="YES"),1,0))) | N28: 28
A29: ='02_ASIN原始数据'!A29 | B29: =IF('02_ASIN原始数据'!L29="","",IF(ISNUMBER('02_ASIN原始数据'!L29),TODAY()-'02_ASIN原始数据'!L29,"")) | C29: =IF(OR(A29="",B29=""),"",IF(B29<='01_动态参数'!B15,1,0)) | D29: =IF(A29="","",IF(AND('02_ASIN原始数据'!D29>='01_动态参数'!B10,'02_ASIN原始数据'!D29<='01_动态参数'!B11),1,0)) | E29: =IF(A29="","",IF('02_ASIN原始数据'!N29>='01_动态参数'!B12,1,0)) | F29: =IF(A29="","",IF('02_ASIN原始数据'!J29>'01_动态参数'!B13,1,0)) | G29: =IF(A29="","",IF('02_ASIN原始数据'!F29>='01_动态参数'!B14,1,0)) | H29: =IF(A29="","",IF('02_ASIN原始数据'!M29="AMZ",1,0)) | I29: =IF(A29="","",IF('02_ASIN原始数据'!E29="", "",RANK('02_ASIN原始数据'!E29,'02_ASIN原始数据'!$E$3:$E$52,0))) | J29: =IF(A29="","",MIN(10,IF('02_ASIN原始数据'!J29<=300,10,IF('02_ASIN原始数据'!J29<=800,8,IF('02_ASIN原始数据'!J29<=1500,5,IF('02_ASIN原始数据'!J29<=3000,2,0))))+IF('02_ASIN原始数据'!P29<=3,2,0)+IF(I29<=10,1,0))) | K29: =IF(A29="","",MIN(10,IF('02_ASIN原始数据'!F29>=50,10,IF('02_ASIN原始数据'!F29>=30,9,IF('02_ASIN原始数据'!F29>=15,7,IF('02_ASIN原始数据'!F29>=5,5,2))))+IF(C29=1,2,0))) | L29: =IF(A29="","",IF(E29=0,0,IF(D29=1,8,3)+IF('02_ASIN原始数据'!N29>='01_动态参数'!B12+10,2,IF('02_ASIN原始数据'!N29>='01_动态参数'!B12,1,0)))) | M29: =IF(A29="","",MIN(10,IF('02_ASIN原始数据'!J29<=500,10,IF('02_ASIN原始数据'!J29<=1000,7,IF('02_ASIN原始数据'!J29<=2000,4,1)))+IF(C29=1,2,0)+IF(OR('02_ASIN原始数据'!Q29="Y",'02_ASIN原始数据'!Q29="Yes",'02_ASIN原始数据'!Q29="YES"),1,0))) | N29: 29
A30: ='02_ASIN原始数据'!A30 | B30: =IF('02_ASIN原始数据'!L30="","",IF(ISNUMBER('02_ASIN原始数据'!L30),TODAY()-'02_ASIN原始数据'!L30,"")) | C30: =IF(OR(A30="",B30=""),"",IF(B30<='01_动态参数'!B15,1,0)) | D30: =IF(A30="","",IF(AND('02_ASIN原始数据'!D30>='01_动态参数'!B10,'02_ASIN原始数据'!D30<='01_动态参数'!B11),1,0)) | E30: =IF(A30="","",IF('02_ASIN原始数据'!N30>='01_动态参数'!B12,1,0)) | F30: =IF(A30="","",IF('02_ASIN原始数据'!J30>'01_动态参数'!B13,1,0)) | G30: =IF(A30="","",IF('02_ASIN原始数据'!F30>='01_动态参数'!B14,1,0)) | H30: =IF(A30="","",IF('02_ASIN原始数据'!M30="AMZ",1,0)) | I30: =IF(A30="","",IF('02_ASIN原始数据'!E30="", "",RANK('02_ASIN原始数据'!E30,'02_ASIN原始数据'!$E$3:$E$52,0))) | J30: =IF(A30="","",MIN(10,IF('02_ASIN原始数据'!J30<=300,10,IF('02_ASIN原始数据'!J30<=800,8,IF('02_ASIN原始数据'!J30<=1500,5,IF('02_ASIN原始数据'!J30<=3000,2,0))))+IF('02_ASIN原始数据'!P30<=3,2,0)+IF(I30<=10,1,0))) | K30: =IF(A30="","",MIN(10,IF('02_ASIN原始数据'!F30>=50,10,IF('02_ASIN原始数据'!F30>=30,9,IF('02_ASIN原始数据'!F30>=15,7,IF('02_ASIN原始数据'!F30>=5,5,2))))+IF(C30=1,2,0))) | L30: =IF(A30="","",IF(E30=0,0,IF(D30=1,8,3)+IF('02_ASIN原始数据'!N30>='01_动态参数'!B12+10,2,IF('02_ASIN原始数据'!N30>='01_动态参数'!B12,1,0)))) | M30: =IF(A30="","",MIN(10,IF('02_ASIN原始数据'!J30<=500,10,IF('02_ASIN原始数据'!J30<=1000,7,IF('02_ASIN原始数据'!J30<=2000,4,1)))+IF(C30=1,2,0)+IF(OR('02_ASIN原始数据'!Q30="Y",'02_ASIN原始数据'!Q30="Yes",'02_ASIN原始数据'!Q30="YES"),1,0))) | N30: 30
A31: ='02_ASIN原始数据'!A31 | B31: =IF('02_ASIN原始数据'!L31="","",IF(ISNUMBER('02_ASIN原始数据'!L31),TODAY()-'02_ASIN原始数据'!L31,"")) | C31: =IF(OR(A31="",B31=""),"",IF(B31<='01_动态参数'!B15,1,0)) | D31: =IF(A31="","",IF(AND('02_ASIN原始数据'!D31>='01_动态参数'!B10,'02_ASIN原始数据'!D31<='01_动态参数'!B11),1,0)) | E31: =IF(A31="","",IF('02_ASIN原始数据'!N31>='01_动态参数'!B12,1,0)) | F31: =IF(A31="","",IF('02_ASIN原始数据'!J31>'01_动态参数'!B13,1,0)) | G31: =IF(A31="","",IF('02_ASIN原始数据'!F31>='01_动态参数'!B14,1,0)) | H31: =IF(A31="","",IF('02_ASIN原始数据'!M31="AMZ",1,0)) | I31: =IF(A31="","",IF('02_ASIN原始数据'!E31="", "",RANK('02_ASIN原始数据'!E31,'02_ASIN原始数据'!$E$3:$E$52,0))) | J31: =IF(A31="","",MIN(10,IF('02_ASIN原始数据'!J31<=300,10,IF('02_ASIN原始数据'!J31<=800,8,IF('02_ASIN原始数据'!J31<=1500,5,IF('02_ASIN原始数据'!J31<=3000,2,0))))+IF('02_ASIN原始数据'!P31<=3,2,0)+IF(I31<=10,1,0))) | K31: =IF(A31="","",MIN(10,IF('02_ASIN原始数据'!F31>=50,10,IF('02_ASIN原始数据'!F31>=30,9,IF('02_ASIN原始数据'!F31>=15,7,IF('02_ASIN原始数据'!F31>=5,5,2))))+IF(C31=1,2,0))) | L31: =IF(A31="","",IF(E31=0,0,IF(D31=1,8,3)+IF('02_ASIN原始数据'!N31>='01_动态参数'!B12+10,2,IF('02_ASIN原始数据'!N31>='01_动态参数'!B12,1,0)))) | M31: =IF(A31="","",MIN(10,IF('02_ASIN原始数据'!J31<=500,10,IF('02_ASIN原始数据'!J31<=1000,7,IF('02_ASIN原始数据'!J31<=2000,4,1)))+IF(C31=1,2,0)+IF(OR('02_ASIN原始数据'!Q31="Y",'02_ASIN原始数据'!Q31="Yes",'02_ASIN原始数据'!Q31="YES"),1,0))) | N31: 31
A32: ='02_ASIN原始数据'!A32 | B32: =IF('02_ASIN原始数据'!L32="","",IF(ISNUMBER('02_ASIN原始数据'!L32),TODAY()-'02_ASIN原始数据'!L32,"")) | C32: =IF(OR(A32="",B32=""),"",IF(B32<='01_动态参数'!B15,1,0)) | D32: =IF(A32="","",IF(AND('02_ASIN原始数据'!D32>='01_动态参数'!B10,'02_ASIN原始数据'!D32<='01_动态参数'!B11),1,0)) | E32: =IF(A32="","",IF('02_ASIN原始数据'!N32>='01_动态参数'!B12,1,0)) | F32: =IF(A32="","",IF('02_ASIN原始数据'!J32>'01_动态参数'!B13,1,0)) | G32: =IF(A32="","",IF('02_ASIN原始数据'!F32>='01_动态参数'!B14,1,0)) | H32: =IF(A32="","",IF('02_ASIN原始数据'!M32="AMZ",1,0)) | I32: =IF(A32="","",IF('02_ASIN原始数据'!E32="", "",RANK('02_ASIN原始数据'!E32,'02_ASIN原始数据'!$E$3:$E$52,0))) | J32: =IF(A32="","",MIN(10,IF('02_ASIN原始数据'!J32<=300,10,IF('02_ASIN原始数据'!J32<=800,8,IF('02_ASIN原始数据'!J32<=1500,5,IF('02_ASIN原始数据'!J32<=3000,2,0))))+IF('02_ASIN原始数据'!P32<=3,2,0)+IF(I32<=10,1,0))) | K32: =IF(A32="","",MIN(10,IF('02_ASIN原始数据'!F32>=50,10,IF('02_ASIN原始数据'!F32>=30,9,IF('02_ASIN原始数据'!F32>=15,7,IF('02_ASIN原始数据'!F32>=5,5,2))))+IF(C32=1,2,0))) | L32: =IF(A32="","",IF(E32=0,0,IF(D32=1,8,3)+IF('02_ASIN原始数据'!N32>='01_动态参数'!B12+10,2,IF('02_ASIN原始数据'!N32>='01_动态参数'!B12,1,0)))) | M32: =IF(A32="","",MIN(10,IF('02_ASIN原始数据'!J32<=500,10,IF('02_ASIN原始数据'!J32<=1000,7,IF('02_ASIN原始数据'!J32<=2000,4,1)))+IF(C32=1,2,0)+IF(OR('02_ASIN原始数据'!Q32="Y",'02_ASIN原始数据'!Q32="Yes",'02_ASIN原始数据'!Q32="YES"),1,0))) | N32: 32
A33: ='02_ASIN原始数据'!A33 | B33: =IF('02_ASIN原始数据'!L33="","",IF(ISNUMBER('02_ASIN原始数据'!L33),TODAY()-'02_ASIN原始数据'!L33,"")) | C33: =IF(OR(A33="",B33=""),"",IF(B33<='01_动态参数'!B15,1,0)) | D33: =IF(A33="","",IF(AND('02_ASIN原始数据'!D33>='01_动态参数'!B10,'02_ASIN原始数据'!D33<='01_动态参数'!B11),1,0)) | E33: =IF(A33="","",IF('02_ASIN原始数据'!N33>='01_动态参数'!B12,1,0)) | F33: =IF(A33="","",IF('02_ASIN原始数据'!J33>'01_动态参数'!B13,1,0)) | G33: =IF(A33="","",IF('02_ASIN原始数据'!F33>='01_动态参数'!B14,1,0)) | H33: =IF(A33="","",IF('02_ASIN原始数据'!M33="AMZ",1,0)) | I33: =IF(A33="","",IF('02_ASIN原始数据'!E33="", "",RANK('02_ASIN原始数据'!E33,'02_ASIN原始数据'!$E$3:$E$52,0))) | J33: =IF(A33="","",MIN(10,IF('02_ASIN原始数据'!J33<=300,10,IF('02_ASIN原始数据'!J33<=800,8,IF('02_ASIN原始数据'!J33<=1500,5,IF('02_ASIN原始数据'!J33<=3000,2,0))))+IF('02_ASIN原始数据'!P33<=3,2,0)+IF(I33<=10,1,0))) | K33: =IF(A33="","",MIN(10,IF('02_ASIN原始数据'!F33>=50,10,IF('02_ASIN原始数据'!F33>=30,9,IF('02_ASIN原始数据'!F33>=15,7,IF('02_ASIN原始数据'!F33>=5,5,2))))+IF(C33=1,2,0))) | L33: =IF(A33="","",IF(E33=0,0,IF(D33=1,8,3)+IF('02_ASIN原始数据'!N33>='01_动态参数'!B12+10,2,IF('02_ASIN原始数据'!N33>='01_动态参数'!B12,1,0)))) | M33: =IF(A33="","",MIN(10,IF('02_ASIN原始数据'!J33<=500,10,IF('02_ASIN原始数据'!J33<=1000,7,IF('02_ASIN原始数据'!J33<=2000,4,1)))+IF(C33=1,2,0)+IF(OR('02_ASIN原始数据'!Q33="Y",'02_ASIN原始数据'!Q33="Yes",'02_ASIN原始数据'!Q33="YES"),1,0))) | N33: 33
A34: ='02_ASIN原始数据'!A34 | B34: =IF('02_ASIN原始数据'!L34="","",IF(ISNUMBER('02_ASIN原始数据'!L34),TODAY()-'02_ASIN原始数据'!L34,"")) | C34: =IF(OR(A34="",B34=""),"",IF(B34<='01_动态参数'!B15,1,0)) | D34: =IF(A34="","",IF(AND('02_ASIN原始数据'!D34>='01_动态参数'!B10,'02_ASIN原始数据'!D34<='01_动态参数'!B11),1,0)) | E34: =IF(A34="","",IF('02_ASIN原始数据'!N34>='01_动态参数'!B12,1,0)) | F34: =IF(A34="","",IF('02_ASIN原始数据'!J34>'01_动态参数'!B13,1,0)) | G34: =IF(A34="","",IF('02_ASIN原始数据'!F34>='01_动态参数'!B14,1,0)) | H34: =IF(A34="","",IF('02_ASIN原始数据'!M34="AMZ",1,0)) | I34: =IF(A34="","",IF('02_ASIN原始数据'!E34="", "",RANK('02_ASIN原始数据'!E34,'02_ASIN原始数据'!$E$3:$E$52,0))) | J34: =IF(A34="","",MIN(10,IF('02_ASIN原始数据'!J34<=300,10,IF('02_ASIN原始数据'!J34<=800,8,IF('02_ASIN原始数据'!J34<=1500,5,IF('02_ASIN原始数据'!J34<=3000,2,0))))+IF('02_ASIN原始数据'!P34<=3,2,0)+IF(I34<=10,1,0))) | K34: =IF(A34="","",MIN(10,IF('02_ASIN原始数据'!F34>=50,10,IF('02_ASIN原始数据'!F34>=30,9,IF('02_ASIN原始数据'!F34>=15,7,IF('02_ASIN原始数据'!F34>=5,5,2))))+IF(C34=1,2,0))) | L34: =IF(A34="","",IF(E34=0,0,IF(D34=1,8,3)+IF('02_ASIN原始数据'!N34>='01_动态参数'!B12+10,2,IF('02_ASIN原始数据'!N34>='01_动态参数'!B12,1,0)))) | M34: =IF(A34="","",MIN(10,IF('02_ASIN原始数据'!J34<=500,10,IF('02_ASIN原始数据'!J34<=1000,7,IF('02_ASIN原始数据'!J34<=2000,4,1)))+IF(C34=1,2,0)+IF(OR('02_ASIN原始数据'!Q34="Y",'02_ASIN原始数据'!Q34="Yes",'02_ASIN原始数据'!Q34="YES"),1,0))) | N34: 34
A35: ='02_ASIN原始数据'!A35 | B35: =IF('02_ASIN原始数据'!L35="","",IF(ISNUMBER('02_ASIN原始数据'!L35),TODAY()-'02_ASIN原始数据'!L35,"")) | C35: =IF(OR(A35="",B35=""),"",IF(B35<='01_动态参数'!B15,1,0)) | D35: =IF(A35="","",IF(AND('02_ASIN原始数据'!D35>='01_动态参数'!B10,'02_ASIN原始数据'!D35<='01_动态参数'!B11),1,0)) | E35: =IF(A35="","",IF('02_ASIN原始数据'!N35>='01_动态参数'!B12,1,0)) | F35: =IF(A35="","",IF('02_ASIN原始数据'!J35>'01_动态参数'!B13,1,0)) | G35: =IF(A35="","",IF('02_ASIN原始数据'!F35>='01_动态参数'!B14,1,0)) | H35: =IF(A35="","",IF('02_ASIN原始数据'!M35="AMZ",1,0)) | I35: =IF(A35="","",IF('02_ASIN原始数据'!E35="", "",RANK('02_ASIN原始数据'!E35,'02_ASIN原始数据'!$E$3:$E$52,0))) | J35: =IF(A35="","",MIN(10,IF('02_ASIN原始数据'!J35<=300,10,IF('02_ASIN原始数据'!J35<=800,8,IF('02_ASIN原始数据'!J35<=1500,5,IF('02_ASIN原始数据'!J35<=3000,2,0))))+IF('02_ASIN原始数据'!P35<=3,2,0)+IF(I35<=10,1,0))) | K35: =IF(A35="","",MIN(10,IF('02_ASIN原始数据'!F35>=50,10,IF('02_ASIN原始数据'!F35>=30,9,IF('02_ASIN原始数据'!F35>=15,7,IF('02_ASIN原始数据'!F35>=5,5,2))))+IF(C35=1,2,0))) | L35: =IF(A35="","",IF(E35=0,0,IF(D35=1,8,3)+IF('02_ASIN原始数据'!N35>='01_动态参数'!B12+10,2,IF('02_ASIN原始数据'!N35>='01_动态参数'!B12,1,0)))) | M35: =IF(A35="","",MIN(10,IF('02_ASIN原始数据'!J35<=500,10,IF('02_ASIN原始数据'!J35<=1000,7,IF('02_ASIN原始数据'!J35<=2000,4,1)))+IF(C35=1,2,0)+IF(OR('02_ASIN原始数据'!Q35="Y",'02_ASIN原始数据'!Q35="Yes",'02_ASIN原始数据'!Q35="YES"),1,0))) | N35: 35
A36: ='02_ASIN原始数据'!A36 | B36: =IF('02_ASIN原始数据'!L36="","",IF(ISNUMBER('02_ASIN原始数据'!L36),TODAY()-'02_ASIN原始数据'!L36,"")) | C36: =IF(OR(A36="",B36=""),"",IF(B36<='01_动态参数'!B15,1,0)) | D36: =IF(A36="","",IF(AND('02_ASIN原始数据'!D36>='01_动态参数'!B10,'02_ASIN原始数据'!D36<='01_动态参数'!B11),1,0)) | E36: =IF(A36="","",IF('02_ASIN原始数据'!N36>='01_动态参数'!B12,1,0)) | F36: =IF(A36="","",IF('02_ASIN原始数据'!J36>'01_动态参数'!B13,1,0)) | G36: =IF(A36="","",IF('02_ASIN原始数据'!F36>='01_动态参数'!B14,1,0)) | H36: =IF(A36="","",IF('02_ASIN原始数据'!M36="AMZ",1,0)) | I36: =IF(A36="","",IF('02_ASIN原始数据'!E36="", "",RANK('02_ASIN原始数据'!E36,'02_ASIN原始数据'!$E$3:$E$52,0))) | J36: =IF(A36="","",MIN(10,IF('02_ASIN原始数据'!J36<=300,10,IF('02_ASIN原始数据'!J36<=800,8,IF('02_ASIN原始数据'!J36<=1500,5,IF('02_ASIN原始数据'!J36<=3000,2,0))))+IF('02_ASIN原始数据'!P36<=3,2,0)+IF(I36<=10,1,0))) | K36: =IF(A36="","",MIN(10,IF('02_ASIN原始数据'!F36>=50,10,IF('02_ASIN原始数据'!F36>=30,9,IF('02_ASIN原始数据'!F36>=15,7,IF('02_ASIN原始数据'!F36>=5,5,2))))+IF(C36=1,2,0))) | L36: =IF(A36="","",IF(E36=0,0,IF(D36=1,8,3)+IF('02_ASIN原始数据'!N36>='01_动态参数'!B12+10,2,IF('02_ASIN原始数据'!N36>='01_动态参数'!B12,1,0)))) | M36: =IF(A36="","",MIN(10,IF('02_ASIN原始数据'!J36<=500,10,IF('02_ASIN原始数据'!J36<=1000,7,IF('02_ASIN原始数据'!J36<=2000,4,1)))+IF(C36=1,2,0)+IF(OR('02_ASIN原始数据'!Q36="Y",'02_ASIN原始数据'!Q36="Yes",'02_ASIN原始数据'!Q36="YES"),1,0))) | N36: 36
A37: ='02_ASIN原始数据'!A37 | B37: =IF('02_ASIN原始数据'!L37="","",IF(ISNUMBER('02_ASIN原始数据'!L37),TODAY()-'02_ASIN原始数据'!L37,"")) | C37: =IF(OR(A37="",B37=""),"",IF(B37<='01_动态参数'!B15,1,0)) | D37: =IF(A37="","",IF(AND('02_ASIN原始数据'!D37>='01_动态参数'!B10,'02_ASIN原始数据'!D37<='01_动态参数'!B11),1,0)) | E37: =IF(A37="","",IF('02_ASIN原始数据'!N37>='01_动态参数'!B12,1,0)) | F37: =IF(A37="","",IF('02_ASIN原始数据'!J37>'01_动态参数'!B13,1,0)) | G37: =IF(A37="","",IF('02_ASIN原始数据'!F37>='01_动态参数'!B14,1,0)) | H37: =IF(A37="","",IF('02_ASIN原始数据'!M37="AMZ",1,0)) | I37: =IF(A37="","",IF('02_ASIN原始数据'!E37="", "",RANK('02_ASIN原始数据'!E37,'02_ASIN原始数据'!$E$3:$E$52,0))) | J37: =IF(A37="","",MIN(10,IF('02_ASIN原始数据'!J37<=300,10,IF('02_ASIN原始数据'!J37<=800,8,IF('02_ASIN原始数据'!J37<=1500,5,IF('02_ASIN原始数据'!J37<=3000,2,0))))+IF('02_ASIN原始数据'!P37<=3,2,0)+IF(I37<=10,1,0))) | K37: =IF(A37="","",MIN(10,IF('02_ASIN原始数据'!F37>=50,10,IF('02_ASIN原始数据'!F37>=30,9,IF('02_ASIN原始数据'!F37>=15,7,IF('02_ASIN原始数据'!F37>=5,5,2))))+IF(C37=1,2,0))) | L37: =IF(A37="","",IF(E37=0,0,IF(D37=1,8,3)+IF('02_ASIN原始数据'!N37>='01_动态参数'!B12+10,2,IF('02_ASIN原始数据'!N37>='01_动态参数'!B12,1,0)))) | M37: =IF(A37="","",MIN(10,IF('02_ASIN原始数据'!J37<=500,10,IF('02_ASIN原始数据'!J37<=1000,7,IF('02_ASIN原始数据'!J37<=2000,4,1)))+IF(C37=1,2,0)+IF(OR('02_ASIN原始数据'!Q37="Y",'02_ASIN原始数据'!Q37="Yes",'02_ASIN原始数据'!Q37="YES"),1,0))) | N37: 37
A38: ='02_ASIN原始数据'!A38 | B38: =IF('02_ASIN原始数据'!L38="","",IF(ISNUMBER('02_ASIN原始数据'!L38),TODAY()-'02_ASIN原始数据'!L38,"")) | C38: =IF(OR(A38="",B38=""),"",IF(B38<='01_动态参数'!B15,1,0)) | D38: =IF(A38="","",IF(AND('02_ASIN原始数据'!D38>='01_动态参数'!B10,'02_ASIN原始数据'!D38<='01_动态参数'!B11),1,0)) | E38: =IF(A38="","",IF('02_ASIN原始数据'!N38>='01_动态参数'!B12,1,0)) | F38: =IF(A38="","",IF('02_ASIN原始数据'!J38>'01_动态参数'!B13,1,0)) | G38: =IF(A38="","",IF('02_ASIN原始数据'!F38>='01_动态参数'!B14,1,0)) | H38: =IF(A38="","",IF('02_ASIN原始数据'!M38="AMZ",1,0)) | I38: =IF(A38="","",IF('02_ASIN原始数据'!E38="", "",RANK('02_ASIN原始数据'!E38,'02_ASIN原始数据'!$E$3:$E$52,0))) | J38: =IF(A38="","",MIN(10,IF('02_ASIN原始数据'!J38<=300,10,IF('02_ASIN原始数据'!J38<=800,8,IF('02_ASIN原始数据'!J38<=1500,5,IF('02_ASIN原始数据'!J38<=3000,2,0))))+IF('02_ASIN原始数据'!P38<=3,2,0)+IF(I38<=10,1,0))) | K38: =IF(A38="","",MIN(10,IF('02_ASIN原始数据'!F38>=50,10,IF('02_ASIN原始数据'!F38>=30,9,IF('02_ASIN原始数据'!F38>=15,7,IF('02_ASIN原始数据'!F38>=5,5,2))))+IF(C38=1,2,0))) | L38: =IF(A38="","",IF(E38=0,0,IF(D38=1,8,3)+IF('02_ASIN原始数据'!N38>='01_动态参数'!B12+10,2,IF('02_ASIN原始数据'!N38>='01_动态参数'!B12,1,0)))) | M38: =IF(A38="","",MIN(10,IF('02_ASIN原始数据'!J38<=500,10,IF('02_ASIN原始数据'!J38<=1000,7,IF('02_ASIN原始数据'!J38<=2000,4,1)))+IF(C38=1,2,0)+IF(OR('02_ASIN原始数据'!Q38="Y",'02_ASIN原始数据'!Q38="Yes",'02_ASIN原始数据'!Q38="YES"),1,0))) | N38: 38
A39: ='02_ASIN原始数据'!A39 | B39: =IF('02_ASIN原始数据'!L39="","",IF(ISNUMBER('02_ASIN原始数据'!L39),TODAY()-'02_ASIN原始数据'!L39,"")) | C39: =IF(OR(A39="",B39=""),"",IF(B39<='01_动态参数'!B15,1,0)) | D39: =IF(A39="","",IF(AND('02_ASIN原始数据'!D39>='01_动态参数'!B10,'02_ASIN原始数据'!D39<='01_动态参数'!B11),1,0)) | E39: =IF(A39="","",IF('02_ASIN原始数据'!N39>='01_动态参数'!B12,1,0)) | F39: =IF(A39="","",IF('02_ASIN原始数据'!J39>'01_动态参数'!B13,1,0)) | G39: =IF(A39="","",IF('02_ASIN原始数据'!F39>='01_动态参数'!B14,1,0)) | H39: =IF(A39="","",IF('02_ASIN原始数据'!M39="AMZ",1,0)) | I39: =IF(A39="","",IF('02_ASIN原始数据'!E39="", "",RANK('02_ASIN原始数据'!E39,'02_ASIN原始数据'!$E$3:$E$52,0))) | J39: =IF(A39="","",MIN(10,IF('02_ASIN原始数据'!J39<=300,10,IF('02_ASIN原始数据'!J39<=800,8,IF('02_ASIN原始数据'!J39<=1500,5,IF('02_ASIN原始数据'!J39<=3000,2,0))))+IF('02_ASIN原始数据'!P39<=3,2,0)+IF(I39<=10,1,0))) | K39: =IF(A39="","",MIN(10,IF('02_ASIN原始数据'!F39>=50,10,IF('02_ASIN原始数据'!F39>=30,9,IF('02_ASIN原始数据'!F39>=15,7,IF('02_ASIN原始数据'!F39>=5,5,2))))+IF(C39=1,2,0))) | L39: =IF(A39="","",IF(E39=0,0,IF(D39=1,8,3)+IF('02_ASIN原始数据'!N39>='01_动态参数'!B12+10,2,IF('02_ASIN原始数据'!N39>='01_动态参数'!B12,1,0)))) | M39: =IF(A39="","",MIN(10,IF('02_ASIN原始数据'!J39<=500,10,IF('02_ASIN原始数据'!J39<=1000,7,IF('02_ASIN原始数据'!J39<=2000,4,1)))+IF(C39=1,2,0)+IF(OR('02_ASIN原始数据'!Q39="Y",'02_ASIN原始数据'!Q39="Yes",'02_ASIN原始数据'!Q39="YES"),1,0))) | N39: 39
A40: ='02_ASIN原始数据'!A40 | B40: =IF('02_ASIN原始数据'!L40="","",IF(ISNUMBER('02_ASIN原始数据'!L40),TODAY()-'02_ASIN原始数据'!L40,"")) | C40: =IF(OR(A40="",B40=""),"",IF(B40<='01_动态参数'!B15,1,0)) | D40: =IF(A40="","",IF(AND('02_ASIN原始数据'!D40>='01_动态参数'!B10,'02_ASIN原始数据'!D40<='01_动态参数'!B11),1,0)) | E40: =IF(A40="","",IF('02_ASIN原始数据'!N40>='01_动态参数'!B12,1,0)) | F40: =IF(A40="","",IF('02_ASIN原始数据'!J40>'01_动态参数'!B13,1,0)) | G40: =IF(A40="","",IF('02_ASIN原始数据'!F40>='01_动态参数'!B14,1,0)) | H40: =IF(A40="","",IF('02_ASIN原始数据'!M40="AMZ",1,0)) | I40: =IF(A40="","",IF('02_ASIN原始数据'!E40="", "",RANK('02_ASIN原始数据'!E40,'02_ASIN原始数据'!$E$3:$E$52,0))) | J40: =IF(A40="","",MIN(10,IF('02_ASIN原始数据'!J40<=300,10,IF('02_ASIN原始数据'!J40<=800,8,IF('02_ASIN原始数据'!J40<=1500,5,IF('02_ASIN原始数据'!J40<=3000,2,0))))+IF('02_ASIN原始数据'!P40<=3,2,0)+IF(I40<=10,1,0))) | K40: =IF(A40="","",MIN(10,IF('02_ASIN原始数据'!F40>=50,10,IF('02_ASIN原始数据'!F40>=30,9,IF('02_ASIN原始数据'!F40>=15,7,IF('02_ASIN原始数据'!F40>=5,5,2))))+IF(C40=1,2,0))) | L40: =IF(A40="","",IF(E40=0,0,IF(D40=1,8,3)+IF('02_ASIN原始数据'!N40>='01_动态参数'!B12+10,2,IF('02_ASIN原始数据'!N40>='01_动态参数'!B12,1,0)))) | M40: =IF(A40="","",MIN(10,IF('02_ASIN原始数据'!J40<=500,10,IF('02_ASIN原始数据'!J40<=1000,7,IF('02_ASIN原始数据'!J40<=2000,4,1)))+IF(C40=1,2,0)+IF(OR('02_ASIN原始数据'!Q40="Y",'02_ASIN原始数据'!Q40="Yes",'02_ASIN原始数据'!Q40="YES"),1,0))) | N40: 40
...

Sheet 04_最终评分
A1: 最终评分 + 一票否决高亮（自动计算）
A2: =IF('00_客户期望配置'!B25="【已完成】可以进入评分","","【警告】请先到「00_客户期望配置」完成所有填写并确认，否则本表结果无效")
A3: asin | B3: title | C3: 低竞争得分 | D3: 生命周期得分 | E3: 利润健康得分 | F3: 准入门槛得分 | G3: 加权总分 | H3: 一票否决 | I3: 推荐等级 | J3: 自动理由 | K3: brand | L3: price
A4: ='03_衍生指标'!A3 | B4: ='02_ASIN原始数据'!B3 | C4: ='03_衍生指标'!J3 | D4: ='03_衍生指标'!K3 | E4: ='03_衍生指标'!L3 | F4: ='03_衍生指标'!M3 | G4: =IF(A4="","",C4*'01_动态参数'!B4+D4*'01_动态参数'!B5+E4*'01_动态参数'!B6+F4*'01_动态参数'!B7) | H4: =IF(A4="","",IF(OR('03_衍生指标'!F3=1,'03_衍生指标'!G3=0,'03_衍生指标'!E3=0,AND('03_衍生指标'!H3=1,'01_动态参数'!B16=1)),"否决","通过")) | I4: =IF(A4="","",IF(H4="否决","淘汰",IF(G4>=8,"S",IF(G4>=7,"A",IF(G4>=6,"B",IF(G4>=5,"C","淘汰")))))) | J4: =IF(A4="","",IF(H4="否决","触发否决："&IF('03_衍生指标'!F3=1,"评分数超限 ","")&IF('03_衍生指标'!G3=0,"增长率不达标 ","")&IF('03_衍生指标'!E3=0,"毛利率不足 ","")&IF(AND('03_衍生指标'!H3=1,'01_动态参数'!B16=1),"自营不接受",""),"推荐：竞争/增长/利润/门槛综合达标")) | K4: ='02_ASIN原始数据'!C3 | L4: ='02_ASIN原始数据'!D3
A5: ='03_衍生指标'!A4 | B5: ='02_ASIN原始数据'!B4 | C5: ='03_衍生指标'!J4 | D5: ='03_衍生指标'!K4 | E5: ='03_衍生指标'!L4 | F5: ='03_衍生指标'!M4 | G5: =IF(A5="","",C5*'01_动态参数'!B4+D5*'01_动态参数'!B5+E5*'01_动态参数'!B6+F5*'01_动态参数'!B7) | H5: =IF(A5="","",IF(OR('03_衍生指标'!F4=1,'03_衍生指标'!G4=0,'03_衍生指标'!E4=0,AND('03_衍生指标'!H4=1,'01_动态参数'!B16=1)),"否决","通过")) | I5: =IF(A5="","",IF(H5="否决","淘汰",IF(G5>=8,"S",IF(G5>=7,"A",IF(G5>=6,"B",IF(G5>=5,"C","淘汰")))))) | J5: =IF(A5="","",IF(H5="否决","触发否决："&IF('03_衍生指标'!F4=1,"评分数超限 ","")&IF('03_衍生指标'!G4=0,"增长率不达标 ","")&IF('03_衍生指标'!E4=0,"毛利率不足 ","")&IF(AND('03_衍生指标'!H4=1,'01_动态参数'!B16=1),"自营不接受",""),"推荐：竞争/增长/利润/门槛综合达标")) | K5: ='02_ASIN原始数据'!C4 | L5: ='02_ASIN原始数据'!D4
A6: ='03_衍生指标'!A5 | B6: ='02_ASIN原始数据'!B5 | C6: ='03_衍生指标'!J5 | D6: ='03_衍生指标'!K5 | E6: ='03_衍生指标'!L5 | F6: ='03_衍生指标'!M5 | G6: =IF(A6="","",C6*'01_动态参数'!B4+D6*'01_动态参数'!B5+E6*'01_动态参数'!B6+F6*'01_动态参数'!B7) | H6: =IF(A6="","",IF(OR('03_衍生指标'!F5=1,'03_衍生指标'!G5=0,'03_衍生指标'!E5=0,AND('03_衍生指标'!H5=1,'01_动态参数'!B16=1)),"否决","通过")) | I6: =IF(A6="","",IF(H6="否决","淘汰",IF(G6>=8,"S",IF(G6>=7,"A",IF(G6>=6,"B",IF(G6>=5,"C","淘汰")))))) | J6: =IF(A6="","",IF(H6="否决","触发否决："&IF('03_衍生指标'!F5=1,"评分数超限 ","")&IF('03_衍生指标'!G5=0,"增长率不达标 ","")&IF('03_衍生指标'!E5=0,"毛利率不足 ","")&IF(AND('03_衍生指标'!H5=1,'01_动态参数'!B16=1),"自营不接受",""),"推荐：竞争/增长/利润/门槛综合达标")) | K6: ='02_ASIN原始数据'!C5 | L6: ='02_ASIN原始数据'!D5
A7: ='03_衍生指标'!A6 | B7: ='02_ASIN原始数据'!B6 | C7: ='03_衍生指标'!J6 | D7: ='03_衍生指标'!K6 | E7: ='03_衍生指标'!L6 | F7: ='03_衍生指标'!M6 | G7: =IF(A7="","",C7*'01_动态参数'!B4+D7*'01_动态参数'!B5+E7*'01_动态参数'!B6+F7*'01_动态参数'!B7) | H7: =IF(A7="","",IF(OR('03_衍生指标'!F6=1,'03_衍生指标'!G6=0,'03_衍生指标'!E6=0,AND('03_衍生指标'!H6=1,'01_动态参数'!B16=1)),"否决","通过")) | I7: =IF(A7="","",IF(H7="否决","淘汰",IF(G7>=8,"S",IF(G7>=7,"A",IF(G7>=6,"B",IF(G7>=5,"C","淘汰")))))) | J7: =IF(A7="","",IF(H7="否决","触发否决："&IF('03_衍生指标'!F6=1,"评分数超限 ","")&IF('03_衍生指标'!G6=0,"增长率不达标 ","")&IF('03_衍生指标'!E6=0,"毛利率不足 ","")&IF(AND('03_衍生指标'!H6=1,'01_动态参数'!B16=1),"自营不接受",""),"推荐：竞争/增长/利润/门槛综合达标")) | K7: ='02_ASIN原始数据'!C6 | L7: ='02_ASIN原始数据'!D6
A8: ='03_衍生指标'!A7 | B8: ='02_ASIN原始数据'!B7 | C8: ='03_衍生指标'!J7 | D8: ='03_衍生指标'!K7 | E8: ='03_衍生指标'!L7 | F8: ='03_衍生指标'!M7 | G8: =IF(A8="","",C8*'01_动态参数'!B4+D8*'01_动态参数'!B5+E8*'01_动态参数'!B6+F8*'01_动态参数'!B7) | H8: =IF(A8="","",IF(OR('03_衍生指标'!F7=1,'03_衍生指标'!G7=0,'03_衍生指标'!E7=0,AND('03_衍生指标'!H7=1,'01_动态参数'!B16=1)),"否决","通过")) | I8: =IF(A8="","",IF(H8="否决","淘汰",IF(G8>=8,"S",IF(G8>=7,"A",IF(G8>=6,"B",IF(G8>=5,"C","淘汰")))))) | J8: =IF(A8="","",IF(H8="否决","触发否决："&IF('03_衍生指标'!F7=1,"评分数超限 ","")&IF('03_衍生指标'!G7=0,"增长率不达标 ","")&IF('03_衍生指标'!E7=0,"毛利率不足 ","")&IF(AND('03_衍生指标'!H7=1,'01_动态参数'!B16=1),"自营不接受",""),"推荐：竞争/增长/利润/门槛综合达标")) | K8: ='02_ASIN原始数据'!C7 | L8: ='02_ASIN原始数据'!D7
A9: ='03_衍生指标'!A8 | B9: ='02_ASIN原始数据'!B8 | C9: ='03_衍生指标'!J8 | D9: ='03_衍生指标'!K8 | E9: ='03_衍生指标'!L8 | F9: ='03_衍生指标'!M8 | G9: =IF(A9="","",C9*'01_动态参数'!B4+D9*'01_动态参数'!B5+E9*'01_动态参数'!B6+F9*'01_动态参数'!B7) | H9: =IF(A9="","",IF(OR('03_衍生指标'!F8=1,'03_衍生指标'!G8=0,'03_衍生指标'!E8=0,AND('03_衍生指标'!H8=1,'01_动态参数'!B16=1)),"否决","通过")) | I9: =IF(A9="","",IF(H9="否决","淘汰",IF(G9>=8,"S",IF(G9>=7,"A",IF(G9>=6,"B",IF(G9>=5,"C","淘汰")))))) | J9: =IF(A9="","",IF(H9="否决","触发否决："&IF('03_衍生指标'!F8=1,"评分数超限 ","")&IF('03_衍生指标'!G8=0,"增长率不达标 ","")&IF('03_衍生指标'!E8=0,"毛利率不足 ","")&IF(AND('03_衍生指标'!H8=1,'01_动态参数'!B16=1),"自营不接受",""),"推荐：竞争/增长/利润/门槛综合达标")) | K9: ='02_ASIN原始数据'!C8 | L9: ='02_ASIN原始数据'!D8
A10: ='03_衍生指标'!A9 | B10: ='02_ASIN原始数据'!B9 | C10: ='03_衍生指标'!J9 | D10: ='03_衍生指标'!K9 | E10: ='03_衍生指标'!L9 | F10: ='03_衍生指标'!M9 | G10: =IF(A10="","",C10*'01_动态参数'!B4+D10*'01_动态参数'!B5+E10*'01_动态参数'!B6+F10*'01_动态参数'!B7) | H10: =IF(A10="","",IF(OR('03_衍生指标'!F9=1,'03_衍生指标'!G9=0,'03_衍生指标'!E9=0,AND('03_衍生指标'!H9=1,'01_动态参数'!B16=1)),"否决","通过")) | I10: =IF(A10="","",IF(H10="否决","淘汰",IF(G10>=8,"S",IF(G10>=7,"A",IF(G10>=6,"B",IF(G10>=5,"C","淘汰")))))) | J10: =IF(A10="","",IF(H10="否决","触发否决："&IF('03_衍生指标'!F9=1,"评分数超限 ","")&IF('03_衍生指标'!G9=0,"增长率不达标 ","")&IF('03_衍生指标'!E9=0,"毛利率不足 ","")&IF(AND('03_衍生指标'!H9=1,'01_动态参数'!B16=1),"自营不接受",""),"推荐：竞争/增长/利润/门槛综合达标")) | K10: ='02_ASIN原始数据'!C9 | L10: ='02_ASIN原始数据'!D9
